Workbook

Sheet Historical Data
A1: Bharti Airtel Limited
A2: Historical Data | L2: ( Rs. In Cr )
C4: Income | H4: 2022 | I4: =H4+1 -> 2023 | J4: =I4+1 -> 2024 | K4: =J4+1 -> 2025 | L4: =K4+1 -> 2026
D5: Revenue from operations | H5: 1165469 | I5: 1391448 | J5: 1499824 | K5: 1729852 | L5: 2109728
D6: Other income | H6: 5343 | I6: 9366 | J6: 14354 | K6: 15737 | L6: 28173
D7: Total income | H7: 1170812 | I7: 1400814 | J7: 1514178 | K7: 1745589 | L7: 2137901
C9: Expenses
D10: Network operating expenses | H10: 250205 | I10: 285433 | J10: 300188 | K10: 335043 | L10: 397500
D11: Access charges | H11: 67611 | I11: 76207 | J11: 75185 | K11: 71713 | L11: 55416
D12: License fee / Spectrum charges | H12: 110636 | I12: 117517 | J12: 120358 | K12: 138290 | L12: 153729
D13: Employee benefits expense | H13: 44333 | I13: 48308 | J13: 53231 | K13: 63089 | L13: 75813
D14: Sales and marketing expenses | H14: 53035 | I14: 72454 | J14: 81326 | K14: 114601 | L14: 131073
D15: Other expenses | H15: 64310 | I15: 78794 | J15: 86618 | K15: 75524 | L15: 99452
D16: Total expenses | H16: 590130 | I16: 678713 | J16: 716906 | K16: 798260 | L16: 912983
C18: EBITDA* (Profit before D&A, finance costs, share of associates'/JVs' profit or loss, exceptional items and tax) | H18: 580682 | I18: 722101 | J18: 797272 | K18: 947329 | L18: 1224918
D19: Depreciation and amortisation expenses | H19: 330907 | I19: 364318 | J19: 395376 | K19: 455703 | L19: 527108
D20: Finance costs | H20: 166162 | I20: 192999 | J20: 226477 | K20: 217539 | L20: 215553
D21: Share of profit / (loss) of associates and joint ventures (net) | H21: 24232 | I21: 7521 | J21: 27094 | K21: 37030 | L21: 3645
C22: Profit before exceptional items and tax | H22: 107845 | I22: 172305 | J22: 202513 | K22: 311117 | L22: 485902
D23: Exceptional items (net) | H23: 16986 | I23: -6698 | J23: -75723 | K23: 72868 | L23: -34175
C24: Profit before tax | H24: 124831 | I24: 165607 | J24: 126790 | K24: 383985 | L24: 451727
D26: Tax expense / (credit)
D27: Current tax | H27: 30331 | I27: 34831 | J27: 41498 | K27: 41121 | L27: 78812
D28: Deferred tax | H28: 11448 | I28: 7902 | J28: -288 | K28: -31949 | L28: 34687
D29: Total tax expense | H29: 41779 | I29: 42733 | J29: 41210 | K29: 9172 | L29: 113499
C30: Profit for the year | H30: 83052 | I30: 122874 | J30: 85580 | K30: 374813 | L30: 338228
A32: Balance Sheet
B33: ASSETS
C34: Non-current assets
D35: Property, plant and equipment | H35: 905725 | I35: 952241 | J35: 1066121 | K35: 1432724 | L35: 1570659
D36: Capital work-in-progress | H36: 42386 | I36: 110293 | J36: 89077 | K36: 105962 | L36: 126131
D37: Right-of-use assets | H37: 322286 | I37: 546466 | J37: 559367 | K37: 602415 | L37: 673244
D38: Goodwill | H38: 338313 | I38: 337741 | J38: 265017 | K38: 516974 | L38: 566859
D39: Other intangible assets | H39: 874509 | I39: 937490 | J39: 1142526 | K39: 1332569 | L39: 1252604
D40: Intangible assets under development | H40: 17161 | I40: 383961 | J40: 79964 | K40: 4027 | L40: 3250
D41: Investment in joint ventures and associates | H41: 284268 | I41: 281838 | J41: 312404 | K41: 36416 | L41: 40622
D42: Financial assets - Investments | H42: 609 | I42: 656 | J42: 924 | K42: 5435 | L42: 11385
D43: Financial assets - Derivative instruments | H43: 218 | I43: 854 | J43: 65
D44: Financial assets - Trade receivables | J44: 1805 | K44: 2131 | L44: 2544
D45: Financial assets - Loans | K45: 865
...

Sheet Model
A1: Bharti Airtel Limited | H1: Historical Period | M1: Forecasted Period
A2: Financial Statement Analysis & Valuation | H2: 2022 | I2: =H2+1 -> 2023 | J2: =I2+1 -> 2024 | K2: =J2+1 -> 2025 | L2: =K2+1 -> 2026 | M2: =L2+1 -> 2027 | N2: =M2+1 -> 2028 | O2: =N2+1 -> 2029 | P2: =O2+1 -> 2030 | Q2: =P2+1 -> 2031
G3: =IF(E4=Scenario!D6,1,IF(E4=Scenario!D7,2,3)) -> 2
B4: LIVE SCENARIO | E4: Bull Case
C5: Revenue Growth as % | I5: =(I20-H20)/H20 -> 0.19389533 | J5: =(J20-I20)/I20 -> 0.077887208 | K5: =(K20-J20)/J20 -> 0.15337 | L5: =(L20-K20)/K20 -> 0.21960029 | M5: {=CHOOSE(G3,Scenario!H6:L6,Scenario!H7:L7,Scenario!H8:L8)} -> 0.2230534 | N5: 0.20089907 | O5: 0.18094517 | P5: 0.16297315 | Q5: 0.14678617
C6: COGS as % of Revenue | H6: =H21/-H20 -> 0.36762196 | I6: =I21/-I20 -> 0.34435854 | J6: =J21/-J20 -> 0.33052612 | K6: =K21/-K20 -> 0.31508245 | L6: =L21/-L20 -> 0.28754655 | M6: =AVERAGE(H6:L6) -> 0.32902712 | N6: =M6 -> 0.32902712 | O6: =N6 -> 0.32902712 | P6: =O6 -> 0.32902712 | Q6: =P6 -> 0.32902712
C7: Operating Expense as % of Revenue | H7: =H23/-H20 -> 0.13872355 | I7: =I23/-I20 -> 0.14341607 | J7: =J23/-J20 -> 0.1474673 | K7: =K23/-K20 -> 0.146379 | L7: =L23/-L20 -> 0.1452026 | M7: =AVERAGE(H7:L7) -> 0.1442377 | N7: =M7 -> 0.1442377 | O7: =N7 -> 0.1442377 | P7: =O7 -> 0.1442377 | Q7: =P7 -> 0.1442377
C8: Depreciation & Amortization as % of PP&E | H8: =H25/-H42 -> 0.34901715 | I8: =I25/-I42 -> 0.34287656 | J8: =J25/-J42 -> 0.34225821 | K8: =K25/-K42 -> 0.29616374 | L8: =L25/-L42 -> 0.31065011 | M8: =AVERAGE(H8:L8) -> 0.32819315 | N8: =M8 -> 0.32819315 | O8: =N8 -> 0.32819315 | P8: =O8 -> 0.32819315 | Q8: =P8 -> 0.32819315
C9: Interest as % of Debt | H9: =H27/-H54 -> 0.097927898 | I9: =I27/-I54 -> 0.085390118 | J9: =J27/-J54 -> 0.10504874 | K9: =K27/-K54 -> 0.10182403 | L9: =L27/-L54 -> 0.11030711 | M9: =AVERAGE(H9:L9) -> 0.10009958 | N9: =M9 -> 0.10009958 | O9: =N9 -> 0.10009958 | P9: =O9 -> 0.10009958 | Q9: =P9 -> 0.10009958
C10: Tax as % of Pre-Tax Income | H10: =H30/-H29 -> 0.33468449 | I10: =I30/-I29 -> 0.25803861 | J10: =J30/-J29 -> 0.32502563 | K10: =K30/-K29 -> 0.02388635 | L10: =L30/-L29 -> 0.25125574 | M10: =AVERAGE(H10:L10) -> 0.23857816 | N10: =M10 -> 0.23857816 | O10: =N10 -> 0.23857816 | P10: =O10 -> 0.23857816 | Q10: =P10 -> 0.23857816
C11: Other Income as % of Revenue | H11: =H28/H20 -> 0.039950441 | I11: =I28/I20 -> 0.0073225877 | J11: =J28/J20 -> -0.022852681 | K11: =K28/K20 -> 0.072627601 | L11: =L28/L20 -> -0.0011172056 | M11: =AVERAGE(H11:L11) -> 0.019186148 | N11: =M11 -> 0.019186148 | O11: =N11 -> 0.019186148 | P11: =O11 -> 0.019186148 | Q11: =P11 -> 0.019186148
C12: Dividend Payout Ratio | H12: =H86/-H31 -> 0.17384289 | I12: =I86/-I31 -> 0.29215294 | J12: =J86/-J31 -> 0.4889577 | K12: =K86/-K31 -> 0.18502293 | L12: =L86/-L31 -> 0.33491314 | M12: =AVERAGE(H12:L12) -> 0.29497792 | N12: =M12 -> 0.29497792 | O12: =N12 -> 0.29497792 | P12: =O12 -> 0.29497792 | Q12: =P12 -> 0.29497792
C13: Day's Sales Outstanding | H13: =H38/H20*365 -> 12.703152 | I13: =I38/I20*365 -> 10.444138 | J13: =J38/J20*365 -> 11.50542 | K13: =K38/K20*365 -> 15.73158 | L13: =L38/L20*365 -> 13.801893 | M13: =AVERAGE(H13:L13) -> 12.837237 | N13: =M13 -> 12.837237 | O13: =N13 -> 12.837237 | P13: =O13 -> 12.837237 | Q13: =P13 -> 12.837237
C14: Day's Inventory Outstanding | H14: =H37/-H21*365 -> 3.1946402 | I14: =I37/-I21*365 -> 1.9622796 | J14: =J37/-J21*365 -> 2.6793463 | K14: =K37/-K21*365 -> 3.0248915 | L14: =L37/-L21*365 -> 3.6154341 | M14: =AVERAGE(H14:L14) -> 2.8953183 | N14: =M14 -> 2.8953183 | O14: =N14 -> 2.8953183 | P14: =O14 -> 2.8953183 | Q14: =P14 -> 2.8953183
C15: Days's Payable Outstanding | H15: =H50/-H21*365 -> 249.38725 | I15: =I50/-I21*365 -> 250.5761 | J15: =J50/-J21*365 -> 258.67582 | K15: =K50/-K21*365 -> 255.50321 | L15: =L50/-L21*365 -> 270.84288 | M15: =AVERAGE(H15:L15) -> 256.99705 | N15: =M15 -> 256.99705 | O15: =N15 -> 256.99705 | P15: =O15 -> 256.99705 | Q15: =P15 -> 256.99705
C16: Capital Asset Turnover Ratio | H16: =H20/(H42+H43) -> 0.63348246 | I16: =I20/(I42+I43) -> 0.58366475 | J16: =J20/(J42+J43) -> 0.63079092 | K16: =K20/(K42+K43) -> 0.60162864 | L16: =L20/(L42+L43) -> 0.71452163 | M16: =AVERAGE(H16:L16) -> 0.63281768 | N16: =M16 -> 0.63281768 | O16: =N16 -> 0.63281768 | P16: =O16 -> 0.63281768 | Q16: =P16 -> 0.63281768
A18: INCOME STATEMENT
C20: Revenue | H20: ='Historical Data'!H5 -> 1165469 | I20: ='Historical Data'!I5 -> 1391448 | J20: ='Historical Data'!J5 -> 1499824 | K20: ='Historical Data'!K5 -> 1729852 | L20: ='Historical Data'!L5 -> 2109728 | M20: =L20*(1+M5) -> 2580310 | N20: =M20*(1+N5) -> 3098691.9 | O20: =N20*(1+O5) -> 3659385.2 | P20: =O20*(1+P5) -> 4255766.8 | Q20: =P20*(1+Q5) -> 4880454.5
C21: Less: Cost of Good Sold | H21: =-SUM('Historical Data'!H10:H12) -> -428452 | I21: =-SUM('Historical Data'!I10:I12) -> -479157 | J21: =-SUM('Historical Data'!J10:J12) -> -495731 | K21: =-SUM('Historical Data'!K10:K12) -> -545046 | L21: =-SUM('Historical Data'!L10:L12) -> -606645 | M21: =M20*-M6 -> -848991.98 | N21: =N20*-N6 -> -1019553.7 | O21: =O20*-O6 -> -1204037 | P21: =P20*-P6 -> -1400262.7 | Q21: =Q20*-Q6 -> -1605801.9
C22: Gross Profit | H22: =SUM(H20:H21) -> 737017 | I22: =SUM(I20:I21) -> 912291 | J22: =SUM(J20:J21) -> 1004093 | K22: =SUM(K20:K21) -> 1184806 | L22: =SUM(L20:L21) -> 1503083 | M22: =SUM(M20:M21) -> 1731318 | N22: =SUM(N20:N21) -> 2079138.2 | O22: =SUM(O20:O21) -> 2455348.2 | ... Q22: =SUM(Q20:Q21) -> 3274652.6
C23: Less: Operating Expense | H23: =-SUM('Historical Data'!H13:H15) -> -161678 | I23: =-SUM('Historical Data'!I13:I15) -> -199556 | J23: =-SUM('Historical Data'!J13:J15) -> -221175 | K23: =-SUM('Historical Data'!K13:K15) -> -253214 | L23: =-SUM('Historical Data'!L13:L15) -> -306338 | M23: =M20*-M7 -> -372177.99 | N23: =N20*-N7 -> -446948.21 | O23: =O20*-O7 -> -527821.33 | P23: =P20*-P7 -> -613842.03 | Q23: =Q20*-Q7 -> -703945.55
C24: EBITDA | H24: =SUM(H22:H23) -> 575339 | I24: =SUM(I22:I23) -> 712735 | J24: =SUM(J22:J23) -> 782918 | K24: =SUM(K22:K23) -> 931592 | L24: =SUM(L22:L23) -> 1196745 | M24: =SUM(M22:M23) -> 1359140 | N24: =SUM(N22:N23) -> 1632190 | O24: =SUM(O22:O23) -> 1927526.9 | ... Q24: =SUM(Q22:Q23) -> 2570707
C25: Less: Depreciation & Amortization | H25: =-'Historical Data'!H19 -> -330907 | I25: =-'Historical Data'!I19 -> -364318 | J25: =-'Historical Data'!J19 -> -395376 | K25: =-'Historical Data'!K19 -> -455703 | L25: =-'Historical Data'!L19 -> -527108 | M25: =M106 -> -969037.55 | N25: =N106 -> -895060.23 | O25: =O106 -> -870151.82 | P25: =P106 -> -875361.84 | Q25: =Q106 -> -897370.65
C26: EBIT | H26: =SUM(H24:H25) -> 244432 | I26: =SUM(I24:I25) -> 348417 | J26: =SUM(J24:J25) -> 387542 | K26: =SUM(K24:K25) -> 475889 | L26: =SUM(L24:L25) -> 669637 | M26: =SUM(M24:M25) -> 390102.5 | N26: =SUM(N24:N25) -> 737129.78 | O26: =SUM(O24:O25) -> 1057375.1 | ... Q26: =SUM(Q24:Q25) -> 1673336.4
C27: Less: Interest | H27: =-'Historical Data'!H20 -> -166162 | I27: =-'Historical Data'!I20 -> -192999 | J27: =-'Historical Data'!J20 -> -226477 | K27: =-'Historical Data'!K20 -> -217539 | L27: =-'Historical Data'!L20 -> -215553 | M27: =M113 -> -195606.29 | N27: =N113 -> -175291.01 | O27: =O113 -> -154975.74 | P27: =P113 -> -134660.46 | Q27: =Q113 -> -114345.19
C28: Other Income | H28: =SUM('Historical Data'!H6,'Historical Data'!H21,'Historical Data'!H23) -> 46561 | I28: =SUM('Historical Data'!I6,'Historical Data'!I21,'Historical Data'!I23) -> 10189 | J28: =SUM('Historical Data'!J6,'Historical Data'!J21,'Historical Data'!J23) -> -34275 | K28: =SUM('Historical Data'!K6,'Historical Data'!K21,'Historical Data'!K23) -> 125635 | L28: =SUM('Historical Data'!L6,'Historical Data'!L21,'Historical Data'!L23) -> -2357 | M28: =M20*M11 -> 49506.211 | N28: =N20*N11 -> 59451.962 | O28: =O20*O11 -> 70209.508 | P28: =P20*P11 -> 81651.773 | Q28: =Q20*Q11 -> 93637.123
C29: Profit Before Tax | H29: =SUM(H26:H28) -> 124831 | I29: =SUM(I26:I28) -> 165607 | J29: =SUM(J26:J28) -> 126790 | K29: =SUM(K26:K28) -> 383985 | L29: =SUM(L26:L28) -> 451727 | M29: =SUM(M26:M28) -> 244002.42 | N29: =SUM(N26:N28) -> 621290.73 | O29: =SUM(O26:O28) -> 972608.86 | ... Q29: =SUM(Q26:Q28) -> 1652628.3
C30: Less: Tax | H30: =-SUM('Historical Data'!H27:H28) -> -41779 | I30: =-SUM('Historical Data'!I27:I28) -> -42733 | J30: =-SUM('Historical Data'!J27:J28) -> -41210 | K30: =-SUM('Historical Data'!K27:K28) -> -9172 | L30: =-SUM('Historical Data'!L27:L28) -> -113499 | M30: =M29*-M10 -> -58213.649 | N30: =N29*-N10 -> -148226.4 | O30: =O29*-O10 -> -232043.24 | P30: =P29*-P10 -> -313322.68 | Q30: =Q29*-Q10 -> -394281.03
C31: Profit After Tax | H31: =SUM(H29:H30) -> 83052 | I31: =SUM(I29:I30) -> 122874 | J31: =SUM(J29:J30) -> 85580 | K31: =SUM(K29:K30) -> 374813 | L31: =SUM(L29:L30) -> 338228 | M31: =SUM(M29:M30) -> 185788.77 | N31: =SUM(N29:N30) -> 473064.33 | O31: =SUM(O29:O30) -> 740565.62 | ... Q31: =SUM(Q29:Q30) -> 1258347.3
A33: BALANCE SHEET
A35: Current Assets
B36: Cash & Bank | H36: ='Historical Data'!H58+'Historical Data'!H57 -> 134943 | I36: ='Historical Data'!I58+'Historical Data'!I57 -> 134186 | J36: ='Historical Data'!J58+'Historical Data'!J57 -> 163399 | K36: ='Historical Data'!K58+'Historical Data'!K57 -> 167199 | L36: ='Historical Data'!L58+'Historical Data'!L57 -> 303768 | M36: =M92 -> 593134.56 | N36: =N92 -> 900108.29 | O36: =O92 -> 1312109.6 | P36: =P92 -> 1862729.8 | Q36: =Q92 -> 2578279.1
B37: Inventories | H37: ='Historical Data'!H53 -> 3750 | I37: ='Historical Data'!I53 -> 2576 | J37: ='Historical Data'!J53 -> 3639 | K37: ='Historical Data'!K53 -> 4517 | L37: ='Historical Data'!L53 -> 6009 | M37: =M21/-365*M14 -> 6734.5261 | N37: =N21/-365*N14 -> 8087.4861 | O37: =O21/-365*O14 -> 9550.8777 | P37: =P21/-365*P14 -> 11107.414 | Q37: =Q21/-365*Q14 -> 12737.829
B38: Trade Recevivable | H38: ='Historical Data'!H56 -> 40562 | I38: ='Historical Data'!I56 -> 39815 | J38: ='Historical Data'!J56 -> 47277 | K38: ='Historical Data'!K56 -> 74557 | L38: ='Historical Data'!L56 -> 79776 | M38: =M20/365*M13 -> 90750.822 | N38: =N13/365*N20 -> 108982.58 | O38: =O13/365*O20 -> 128702.45 | P38: =P13/365*P20 -> 149677.49 | Q38: =Q13/365*Q20 -> 171648.08
B39: Other Current Assets | H39: =SUM('Historical Data'!H59:H61,'Historical Data'!H54:H55) -> 341024 | I39: =SUM('Historical Data'!I59:I61,'Historical Data'!I54:I55) -> 398436 | J39: =SUM('Historical Data'!J59:J61,'Historical Data'!J54:J55) -> 368446 | K39: =SUM('Historical Data'!K59:K61,'Historical Data'!K54:K55) -> 429615 | L39: =SUM('Historical Data'!L59:L61,'Historical Data'!L54:L55) -> 512601 | M39: =L39 -> 512601 | N39: =M39 -> 512601 | O39: =N39 -> 512601 | P39: =O39 -> 512601 | Q39: =P39 -> 512601
A41: Non Current Assets
B42: Plant, Property & Equipment | H42: ='Historical Data'!H35+'Historical Data'!H36 -> 948111 | I42: ='Historical Data'!I35+'Historical Data'!I36 -> 1062534 | J42: ='Historical Data'!J35+'Historical Data'!J36 -> 1155198 | K42: ='Historical Data'!K35+'Historical Data'!K36 -> 1538686 | L42: ='Historical Data'!L35+'Historical Data'!L36 -> 1696790 | M42: =M107-M43 -> 1471382.1 | N42: =N107-N43 -> 1395486.6 | O42: =O107-O43 -> 1411361.4 | P42: =P107-P43 -> 1478421.9 | Q42: =Q107-Q43 -> 1568204
B43: Intangible Assets | H43: ='Historical Data'!H39+'Historical Data'!H40 -> 891670 | I43: ='Historical Data'!I39+'Historical Data'!I40 -> 1321451 | J43: ='Historical Data'!J39+'Historical Data'!J40 -> 1222490 | K43: ='Historical Data'!K39+'Historical Data'!K40 -> 1336596 | L43: ='Historical Data'!L39+'Historical Data'!L40 -> 1255854 | M43: =L43 -> 1255854 | N43: =M43 -> 1255854 | O43: =N43 -> 1255854 | P43: =O43 -> 1255854 | Q43: =P43 -> 1255854
B44: Goodwill | H44: ='Historical Data'!H38 -> 338313 | I44: ='Historical Data'!I38 -> 337741 | J44: ='Historical Data'!J38 -> 265017 | K44: ='Historical Data'!K38 -> 516974 | L44: ='Historical Data'!L38 -> 566859 | M44: =L44 -> 566859 | N44: =M44 -> 566859 | O44: =N44 -> 566859 | P44: =O44 -> 566859 | Q44: =P44 -> 566859
B45: Financial Asset | H45: =SUM('Historical Data'!H42:H46) -> 23342 | I45: =SUM('Historical Data'!I42:I46) -> 27473 | J45: =SUM('Historical Data'!J42:J46) -> 29351 | K45: =SUM('Historical Data'!K42:K46) -> 45902 | L45: =SUM('Historical Data'!L42:L46) -> 49629 | M45: =L45 -> 49629 | N45: =M45 -> 49629 | O45: =N45 -> 49629 | P45: =O45 -> 49629 | Q45: =P45 -> 49629
...

Sheet Re-Payment
A1: Bharti Airtel Limited
A2: Loan Repayment & Lease Liabilities
D4: Instrument | H4: 2026 | I4: 2027 | J4: 2028* | K4: 2029 | L4: 2030 | M4: 2031+ | N4: Total
D5: Term loans — One time | H5: 55231 | I5: 25347 | J5: 1344.6667 | K5: 1344.6667 | L5: 1344.6667 | M5: 0 | N5: =SUM(H5:M5) -> 84612
D6: Term loans — Monthly | H6: 6714 | I6: 7075 | J6: 2204.3333 | K6: 2204.3333 | L6: 2204.3333 | M6: 658 | N6: =SUM(H6:M6) -> 21060
D7: Term loans — Quarterly | H7: 18592 | I7: 8536 | J7: 3673 | K7: 3673 | L7: 3673 | M7: 1078 | N7: =SUM(H7:M7) -> 39225
D8: Term loans — Half yearly | H8: 27665 | I8: 13328 | J8: 11480.667 | K8: 11480.667 | L8: 11480.667 | M8: 7293 | N8: =SUM(H8:M8) -> 82728
D9: Term loans — Annually | H9: 3278 | I9: 3278 | J9: 0 | K9: 0 | L9: 0 | M9: 0 | N9: =SUM(H9:M9) -> 6556
D10: Non-convertible bonds | H10: 0 | I10: 0 | J10: 0 | K10: 0 | L10: 0 | M10: 70955 | N10: =SUM(H10:M10) -> 70955
D11: Deferred payment liability — Spectrum | H11: 20727 | I11: 22237 | J11: 25636.667 | K11: 25636.667 | L11: 25636.667 | M11: 423395 | N11: =SUM(H11:M11) -> 543269
D12: Deferred payment liability — Adjusted Gross Revenue (AGR) | H12: 58614 | I12: 63303 | J12: 73982 | K12: 73982 | L12: 73982 | M12: 0 | N12: =SUM(H12:M12) -> 343863
D13: Bank overdraft | H13: 25436 | I13: 0 | J13: 0 | K13: 0 | L13: 0 | M13: 0 | N13: =SUM(H13:M13) -> 25436
D14: Total borrowings repayment | H14: =SUM(H5:H13) -> 216257 | I14: =SUM(I5:I13) -> 143104 | J14: =SUM(J5:J13) -> 118321.33 | K14: =SUM(K5:K13) -> 118321.33 | L14: =SUM(L5:L13) -> 118321.33 | M14: =SUM(M5:M13) -> 503379 | N14: =SUM(H14:M14) -> 1217704

Sheet Scenario
A1: Bharti Airtel Limited
A2: LIVE SCEANRIO
D5: Scenarios | E5: Growth % | H5: =Model!M2 -> 2027 | I5: =Model!N2 -> 2028 | J5: =Model!O2 -> 2029 | K5: =Model!P2 -> 2030 | L5: =Model!Q2 -> 2031
D6: Base Case | E6: =AVERAGE(Model!I5:L5) -> 0.16118821 | H6: =E6 -> 0.16118821 | I6: =H6*(1-$E$8) -> 0.14517851 | J6: =I6*(1-$E$8) -> 0.13075894 | K6: =J6*(1-$E$8) -> 0.11777157 | L6: =K6*(1-$E$8) -> 0.10607414
D7: Bull Case | E7: =+ABS(E6+STDEV(Model!I5:L5)) -> 0.2230534 | H7: =E7 -> 0.2230534 | I7: =H7*(1-$E$8) -> 0.20089907 | J7: =I7*(1-$E$8) -> 0.18094517 | K7: =J7*(1-$E$8) -> 0.16297315 | L7: =K7*(1-$E$8) -> 0.14678617
D8: Bear Case | E8: =+ABS(E6-STDEV(Model!I5:L5)) -> 0.099323008 | H8: =E8 -> 0.099323008 | I8: =H8*(1-$E$8) -> 0.089457948 | J8: =I8*(1-$E$8) -> 0.080572716 | K8: =J8*(1-$E$8) -> 0.072569991 | L8: =K8*(1-$E$8) -> 0.065362121
D9: Annual growth tapering | E9: =10% -> 0.1

Sheet Market Data
A1: Bharti Airtel Limited
A2: Market Data
E4: Index
D5: Date | E5: Close Price
D6: 46230 | E6: 23995.95 | H6: Period (yrs) | J6: 9
D7: 46227 | E7: 23767.45
D8: 46226 | E8: 23869.6 | H8: Returns | J8: =_xlfn.RRI(J6,E2622,E6) -> 0.13038872
D9: 46225 | E9: 23996.25
D10: 46224 | E10: 24187.7
D11: 46223 | E11: 24238.5
D12: 46220 | E12: 24334.3
D13: 46219 | E13: 24072.75
D14: 46218 | E14: 24078.5
D15: 46217 | E15: 24052.05
D16: 46216 | E16: 24211
D17: 46213 | E17: 24206.9
D18: 46212 | E18: 23962.8
D19: 46211 | E19: 23882.05
D20: 46210 | E20: 24398.7
... D2622: 42370 | E2622: 7963.2

Sheet WACC
A1: Bharti Airtel Limited
A2: Weighted-Average Cost of Capital (WACC)
A3: (All Amounts Denominated in INR Crore Unless Otherwise Stated)
A5: Comparable Companies Beta
H7: Equity | I7: Total | J7: Debt/ | K7: Debt/ | L7: Tax | M7: Levered | N7: Unlevered
D8: Company Name | H8: Value | I8: Debt | J8: Equity | K8: Capital | L8: Rate % | M8: Beta | N8: Beta
D9: Vodafone Idea Limited | H9: =Comp!K8 -> 1615403.3 | I9: =Comp!L8 -> 1925280 | J9: =I9/H9 -> 1.1918262 | K9: =I9/(H9+I9) -> 0.54375945 | L9: =Model!M10 -> 0.23857816 | M9: 1.75 | N9: =M9/(1+J9*(1-K9)) -> 1.1335963
D10: Bharti Hexacom Limited | H10: =Comp!K9 -> 825000 | I10: =Comp!L9 -> 26943 | J10: =I10/H10 -> 0.032658182 | K10: =I10/(H10+I10) -> 0.031625355 | L10: =L9 -> 0.23857816 | M10: 0.55 | N10: =M10/(1+J10*(1-K10)) -> 0.53313928
D11: Tata Communications Limited | H11: =Comp!K10 -> 513000 | I11: =Comp!L10 -> 122624 | J11: =I11/H11 -> 0.23903314 | K11: =I11/(H11+I11) -> 0.19291908 | L11: =L10 -> 0.23857816 | M11: 0.85 | N11: =M11/(1+J11*(1-K11)) -> 0.71253785
D12: Railtel Corporation of India Limited | H12: =Comp!K11 -> 96282 | I12: =Comp!L11 -> 637.2 | J12: =I12/H12 -> 0.0066180595 | K12: =I12/(H12+I12) -> 0.0065745487 | L12: =L11 -> 0.23857816 | M12: 0.7 | N12: =M12/(1+J12*(1-K12)) -> 0.69542788
D13: Average | J13: =AVERAGE(J9:J12) -> 0.36753389 | K13: =AVERAGE(K9:K12) -> 0.19371961 | L13: =AVERAGE(L9:L12) -> 0.23857816 | M13: =AVERAGE(M9:M12) -> 0.9625 | N13: =AVERAGE(N9:N12) -> 0.76867533
D14: Median | J14: =MEDIAN(J9:J12) -> 0.13584566 | K14: =MEDIAN(K9:K12) -> 0.11227222 | L14: =MEDIAN(L9:L12) -> 0.23857816 | M14: =MEDIAN(M9:M12) -> 0.775 | N14: =MEDIAN(N9:N12) -> 0.70398286
D16: Bharti Airtel Limited | H16: =Comp!K16 -> 11273160 | I16: =Comp!L16 -> 1954117
D18: WACC Calculation
C20: Target Capital Structure
D21: Proportion of Debt | I21: =Comp!L16/(Comp!K16+Comp!L16) -> 0.14773388
D22: Proportion of Equity | I22: =1-I21 -> 0.85226612
C25: Current Capital Structure
D26: Market Cap | I26: =H16 -> 11273160
D27: Total Debt | I27: =I16 -> 1954117
D28: Debt / Equity | I28: =I27/I26 -> 0.17334243
C30: Cost of Debt
D31: Pre-Tax Cost of Debt | I31: =Model!M9 -> 0.10009958
D32: Tax Rate | I32: =Model!M10 -> 0.23857816
D33: After-Tax Cost of Debt | I33: =I31*(1-I32) -> 0.076218006
C35: Cost of Equity
D36: Risk Free Rate | I36: 0.065
D37: Equity Market Return | I37: ='Market Data'!J8 -> 0.13038872
D38: Equity Risk Premium | I38: =I37-I36 -> 0.065388717
D39: Levered Equity Beta | I39: =N14*(1+I28)*(1-I32) -> 0.62894431
D40: Cost of Equity | I40: =I36+I39*I38 -> 0.10612586
D42: WACC | I42: =(I21*I33)+(I40*I22) -> 0.10170746

Sheet Comp Data
A1: Bharti Airtel Limited | H1: \
A2: Comp Data
D4: Company | H4: Ticker | I4: Price | J4: Shares | K4: Debt | L4: Cash | M4: Sales | N4: EBITDA | O4: Net Income
D5: Bharti Airtel Limited | H5: BHARTIARTL | I5: 1850 | J5: 6093.6 | K5: 1954117 | L5: 303768 | M5: 2109728 | N5: 1196745 | O5: 338228
D7: Vodafone Idea Limited | H7: IDEA | I7: 14.92 | J7: 108271 | K7: 1925280 | L7: 57310 | M7: 455390 | N7: 194251 | O7: 374058
D8: Bharti Hexacom Limited | H8: BHARTIHEXA | I8: 1650 | J8: 500 | K8: 26943 | L8: 330 | M8: 96010 | N8: 50519 | O8: 18240
D9: Tata Communications Limited | H9: TATACOMM | I9: 1800 | J9: 285 | K9: 122624 | L9: 9905 | M9: 254260 | N9: 49158 | O9: 9058
D10: Railtel Corporation of India Limited | H10: RAILTEL | I10: 300 | J10: 320.94 | K10: 637.2 | L10: 6541.1 | M10: 44270 | N10: 6521.8 | O10: 3460
D12: Source: www.screener.in

Sheet Comp
A1: Bharti Airtel Limited
A2: Comp Valuation
I5: Market Data | P5: Financial Data | T5: Valuation
I6: Price | J6: Shares | K6: Market Cap | L6: Debt | M6: Cash | N6: EV | P6: Sales | Q6: EBITDA | R6: Earnings | T6: EV/Sales | U6: EV/EBITDA | V6: P/E
D7: Company Name | F7: Ticker | I7: (₹/share) | J7: ₹ In CR | K7: ₹ In CR | M7: & Equivalents | N7: ₹ In CR | P7: ₹ In CR | Q7: ₹ In CR | R7: ₹ In CR | T7: x | U7: x | V7: x
D8: Vodafone Idea Limited | F8: IDEA | I8: ='Comp Data'!I7 -> 14.92 | J8: ='Comp Data'!J7 -> 108271 | K8: =I8*J8 -> 1615403.3 | L8: ='Comp Data'!K7 -> 1925280 | M8: ='Comp Data'!L7 -> 57310 | N8: =K8+L8-M8 -> 3483373.3 | P8: ='Comp Data'!M7 -> 455390 | Q8: ='Comp Data'!N7 -> 194251 | R8: ='Comp Data'!O7 -> 374058 | T8: =N8/P8 -> 7.6492091 | U8: =N8/Q8 -> 17.932331 | V8: =K8/R8 -> 4.3185905
D9: Bharti Hexacom Limited | F9: BHARTIHEXA | I9: ='Comp Data'!I8 -> 1650 | J9: ='Comp Data'!J8 -> 500 | K9: =I9*J9 -> 825000 | L9: ='Comp Data'!K8 -> 26943 | M9: ='Comp Data'!L8 -> 330 | N9: =K9+L9-M9 -> 851613 | P9: ='Comp Data'!M8 -> 96010 | Q9: ='Comp Data'!N8 -> 50519 | R9: ='Comp Data'!O8 -> 18240 | T9: =N9/P9 -> 8.8700448 | U9: =N9/Q9 -> 16.857281 | V9: =K9/R9 -> 45.230263
D10: Tata Communications Limited | F10: TATACOMM | I10: ='Comp Data'!I9 -> 1800 | J10: ='Comp Data'!J9 -> 285 | K10: =I10*J10 -> 513000 | L10: ='Comp Data'!K9 -> 122624 | M10: ='Comp Data'!L9 -> 9905 | N10: =K10+L10-M10 -> 625719 | P10: ='Comp Data'!M9 -> 254260 | Q10: ='Comp Data'!N9 -> 49158 | R10: ='Comp Data'!O9 -> 9058 | T10: =N10/P10 -> 2.4609416 | U10: =N10/Q10 -> 12.728732 | V10: =K10/R10 -> 56.635019
D11: Railtel Corporation of India Limited | F11: RAILTEL | I11: ='Comp Data'!I10 -> 300 | J11: ='Comp Data'!J10 -> 320.94 | K11: =I11*J11 -> 96282 | L11: ='Comp Data'!K10 -> 637.2 | M11: ='Comp Data'!L10 -> 6541.1 | N11: =K11+L11-M11 -> 90378.1 | P11: ='Comp Data'!M10 -> 44270 | Q11: ='Comp Data'!N10 -> 6521.8 | R11: ='Comp Data'!O10 -> 3460 | T11: =N11/P11 -> 2.0415202 | U11: =N11/Q11 -> 13.857846 | V11: =K11/R11 -> 27.827168
D13: Average | T13: =AVERAGE(T8:T11) -> 5.2554289 | U13: =AVERAGE(U8:U11) -> 15.344048 | V13: =AVERAGE(V8:V11) -> 33.50276
D14: Median | T14: =MEDIAN(T8:T11) -> 5.0550753 | U14: =MEDIAN(U8:U11) -> 15.357564 | V14: =MEDIAN(V8:V11) -> 36.528715
D16: Bharti Airtel Limited | I16: ='Comp Data'!I5 -> 1850 | J16: ='Comp Data'!J5 -> 6093.6 | K16: =I16*J16 -> 11273160 | L16: ='Comp Data'!K5 -> 1954117 | M16: ='Comp Data'!L5 -> 303768 | N16: =K16+L16-M16 -> 12923509 | P16: ='Comp Data'!M5 -> 2109728 | Q16: ='Comp Data'!N5 -> 1196745 | R16: ='Comp Data'!O5 -> 338228
D18: Metric | F18: Comps | I18: EV | J18: Net Debt | K18: Equity Value | L18: Shares | M18: Share Price
D19: =T6 -> EV/Sales | F19: =T14 -> 5.0550753 | I19: =F19*P16 -> 10664834 | J19: =L16-M16 -> 1650349 | K19: =I19-J19 -> 9014484.9 | L19: =J16 -> 6093.6 | M19: =K19/L19 -> 1479.3365
D20: =U6 -> EV/EBITDA | F20: =U14 -> 15.357564 | I20: =F20*Q16 -> 18379088 | J20: =J19 -> 1650349 | K20: =I20-J20 -> 16728739 | L20: =L19 -> 6093.6 | M20: =K20/L20 -> 2745.2965
D21: =V6 -> P/E | F21: =V14 -> 36.528715 | I21: =F21*R16 -> 12355034 | J21: =J20 -> 1650349 | K21: =I21-J21 -> 10704685 | L21: =L20 -> 6093.6 | M21: =K21/L21 -> 1756.7096

Sheet Football Field
A1: Bharti Airtel Limited
A2: FootBall Field Chart
E4: Comps | F4: DCF | G4: 52-week high/low | H4: Market Consensus
D5: High | E5: =E6 -> 2745.2965 | F5: =F6 -> 3225.7273 | G5: =G6 -> 2175 | H5: =H6 -> 2410
D6: High | E6: =Comp!M20 -> 2745.2965 | F6: 3225.7273 | G6: 2175 | H6: 2410 | I6: (ICICI Securities)
D7: Low | E7: =Comp!M19 -> 1479.3365 | F7: 2817.9719 | G7: 1740 | H7: 2180 | I7: (Prabhudas Lilladher)
D8: Low | E8: =E7 -> 1479.3365 | F8: =F7 -> 2817.9719 | G8: =G7 -> 1740 | H8: =H7 -> 2180
A10: FootBall Field Chart
