Workbook

Sheet Historical Data
A1: Alkem Laboratories Limited
A2: Historical Financial Data | L2: (Rs. In Million)
B4: Income | H4: 2021 | I4: =H4+1 -> 2022 | J4: =I4+1 -> 2023 | K4: =J4+1 -> 2024 | L4: =K4+1 -> 2025
C5: Revenue from operations | H5: 88650.1 | I5: 106341.9 | J5: 115992.6 | K5: 126675.8 | L5: 129645.2
C6: Other income | H6: 2332.1 | I6: 1626.5 | J6: 2160.8 | K6: 3108.4 | L6: 4937.4
C7: Total income | H7: 90982.2 | I7: 107968.4 | J7: 118153.4 | K7: 129784.2 | L7: 134582.6
B8: Expenses
C9: Cost of materials consumed | H9: 23945.4 | I9: 32260.6 | J9: 30569.2 | K9: 32945.9 | L9: 34403.7
C10: Purchases of stock-in-trade | H10: 14377.6 | I10: 14897.1 | J10: 13875.5 | K10: 16288.7 | L10: 15140.2
C11: Changes in inventories of finished goods, work-in-progress and stock-in-trade | H11: -3338.4 | I11: -5354.8 | J11: 4623.7 | K11: 141.2 | L11: -1901.3
C12: Employee benefits expense | H12: 16210.3 | I12: 19627.1 | J12: 21313.5 | K12: 22010.1 | L12: 24539.2
C13: Finance costs | H13: 589.2 | I13: 523.7 | J13: 1073.6 | K13: 1124.1 | L13: 1217
C14: Depreciation and amortisation expenses | H14: 2745.8 | I14: 3039.6 | J14: 3104.2 | K14: 2993 | L14: 3571.6
C15: Other expenses | H15: 18031.3 | I15: 24382.7 | J15: 29516.2 | K15: 32835 | L15: 32341.9
C16: Total expenses | H16: 72561.2 | I16: 89376 | J16: 104075.9 | K16: 108338 | L16: 109312.3
C17: Profit before exceptional items and tax (1) - (2) | H17: 18421 | I17: 18592.4 | J17: 14077.5 | K17: 21446.2 | L17: 25270.3
C18: Exceptional items | H18: 0 | I18: -149.6 | J18: -1029.8 | K18: -1214.9
C19: Profit before tax (3) + (4) | H19: 18421 | I19: 18442.8 | J19: 13047.7 | K19: 20231.3 | L19: 25270.3
C20: Current tax | H20: 3965.3 | I20: 3619.8 | J20: 2739 | K20: 4222.8 | L20: 5236
C21: Deferred tax credit (net) | H21: -1722 | I21: -1980.2 | J21: 240.6 | K21: -2106.1 | L21: -2125.7
C22: Total tax expenses (a + b) | H22: 2243.3 | I22: 1639.6 | J22: 2979.6 | K22: 2116.7 | L22: 3110.3
C23: Share in loss after tax of associate | L23: -6.2
C24: Profit for the year (5) - (6) + (7) | H24: 16177.7 | I24: 16803.2 | J24: 10068.1 | K24: 18114.6 | L24: 22153.8
C26: Balance Sheet
C28: ASSETS
C29: Non-current assets
C30: Property, plant and equipment | H30: 22339.3 | I30: 22871 | J30: 20654 | K30: 21614.6 | L30: 20639.3
C31: Right of use assets | J31: 1378.5 | K31: 2471.7 | L31: 3222.2
C32: Capital work in progress | H32: 3932.8 | I32: 3394.8 | J32: 3102.7 | K32: 1484 | L32: 4765.5
C33: Goodwill | H33: 3953.9 | I33: 4030.9 | J33: 4131.7 | K33: 4167.4 | L33: 4231.1
C34: Other intangible assets | H34: 1636.6 | I34: 2115.4 | J34: 664.1 | K34: 474.1 | L34: 430.5
C35: Intangible assets under development | J35: 129.7 | K35: 101.7 | L35: 715.2
C36: Financial assets
C37: Investment in associate | H37: 1539.5 | I37: 2316.7 | J37: 3046.1 | K37: - | L37: 323.8
C38: Other investments | H38: 80.2 | I38: 80.2 | J38: 80.2 | K38: 3348 | L38: 9108.6
C39: Other financial assets | H39: 607.9 | I39: 7106.7 | J39: 2952.5 | K39: 1202.2 | L39: 4753.6
C40: Other non-current assets | H40: 11079.1 | I40: 13092.6 | J40: 13025 | K40: 15148.3 | L40: 17382.5
C41: Deferred tax assets (net) | H41: 171.1 | I41: 533.1 | J41: 575.4 | K41: 781.7 | L41: 647.1
C42: Current tax assets (net) | H42: 564 | I42: 796.2 | J42: 529.6 | K42: 839.5 | L42: 1233.4
C43: Total non-current assets | H43: 45904.4 | I43: 56337.6 | J43: 50269.5 | K43: 51633.2 | L43: 67452.8
...

Sheet Model
A1: Alkem Laboratories Limited | H1: Historical Period | M1: Forecasting Period
A2: Financial Statement Analysis & Valuation | H2: ='Historical Data'!H4 -> 2021 | I2: ='Historical Data'!I4 -> 2022 | J2: ='Historical Data'!J4 -> 2023 | K2: ='Historical Data'!K4 -> 2024 | L2: ='Historical Data'!L4 -> 2025 | M2: 2026 | N2: 2027 | O2: 2028 | P2: 2029 | Q2: 2030
A4: Ratio's & Assumptions
D6: LIVE SCENARIO | E6: Base Case | H6: =IF(E6=Scenarios!D5,1,IF(E6=Scenarios!D6,2,3)) -> 1
D7: Revenue Growth % | I7: =I22/H22-1 -> 0.19956887 | J7: =J22/I22-1 -> 0.090751623 | K7: =K22/J22-1 -> 0.092102427 | L7: =L22/K22-1 -> 0.023440941 | M7: {=CHOOSE(H6,Scenarios!H5:L5,Scenarios!H6:L6,Scenarios!H7:L7)} -> 0.10146596 | N7: 0.091319368 | O7: 0.082187431 | P7: 0.073968688 | Q7: 0.066571819
D8: COGS as % of revenue | H8: =-H23/H22 -> 0.39463689 | I8: =-I23/I22 -> 0.39309905 | J8: =-J23/J22 -> 0.42303043 | K8: =-K23/K22 -> 0.38978084 | L8: =-L23/L22 -> 0.36748449 | M8: =AVERAGE(H8:L8) -> 0.39360634 | N8: =M8 -> 0.39360634 | O8: =N8 -> 0.39360634 | P8: =O8 -> 0.39360634 | Q8: =P8 -> 0.39360634
D9: Operating Exp as % of revenue | H9: =-H25/H22 -> 0.38625563 | I9: =-I25/I22 -> 0.41385192 | J9: =-J25/J22 -> 0.43821502 | K9: =-K25/K22 -> 0.43295641 | L9: =-L25/L22 -> 0.43874436 | M9: =AVERAGE(H9:L9) -> 0.42200467 | N9: =M9 -> 0.42200467 | O9: =N9 -> 0.42200467 | P9: =O9 -> 0.42200467 | Q9: =P9 -> 0.42200467
D10: Depreciation as % of PPE | H10: =-H27/(H44+H45) -> 0.098385091 | I10: =-I27/(I44+I45) -> 0.10709907 | J10: =-J27/(J44+J45) -> 0.11971923 | K10: =-K27/(K44+K45) -> 0.11447214 | L10: =-L27/(L44+L45) -> 0.11996225 | M10: =AVERAGE(H10:L10) -> 0.11192756 | N10: =M10 -> 0.11192756 | O10: =N10 -> 0.11192756 | P10: =O10 -> 0.11192756 | Q10: =P10 -> 0.11192756
D11: Interest as % of Debt | H11: =-H29/H56 -> 0.032879831 | I11: =-I29/I56 -> 0.019627538 | J11: =-J29/J56 -> 0.076868001 | K11: =-K29/K56 -> 0.07925071 | L11: =-L29/L56 -> 0.088130929 | M11: =AVERAGE(H11:L11) -> 0.059351402 | N11: =M11 -> 0.059351402 | O11: =N11 -> 0.059351402 | P11: =O11 -> 0.059351402 | Q11: =P11 -> 0.059351402
D12: Other Income as % of revenue | H12: =H30/H22 -> 0.026306795 | I12: =I30/I22 -> 0.013888223 | J12: =J30/J22 -> 0.009750622 | K12: =K30/K22 -> 0.014947606 | L12: =L30/L22 -> 0.03808394 | M12: =AVERAGE(H12:L12) -> 0.020595437 | N12: =M12 -> 0.020595437 | O12: =N12 -> 0.020595437 | P12: =O12 -> 0.020595437 | Q12: =P12 -> 0.020595437
D13: Taxes as % of Pre-Tax Income | H13: =-H32/H31 -> 0.12177949 | I13: =-I32/I31 -> 0.088901902 | J13: =-J32/J31 -> 0.22836209 | K13: =-K32/K31 -> 0.10462501 | L13: =-L32/L31 -> 0.12308125 | M13: =AVERAGE(H13:L13) -> 0.13334995 | N13: =M13 -> 0.13334995 | O13: =N13 -> 0.13334995 | P13: =O13 -> 0.13334995 | Q13: =P13 -> 0.13334995
D14: Dividend Payout Ratio | H14: =-H89/H33 -> 0.20693918 | I14: =-I89/I33 -> 0.25108908 | J14: =-J89/J33 -> 0.52593836 | K14: =-K89/K33 -> 0.29837258 | L14: =-L89/L33 -> 0.22771661 | M14: =AVERAGE(H14:L14) -> 0.30201116 | N14: =M14 -> 0.30201116 | O14: =N14 -> 0.30201116 | P14: =O14 -> 0.30201116 | Q14: =P14 -> 0.30201116
D15: Days Sales Outstanding | H15: =H40/H22*365 -> 66.173828 | I15: =I40/I22*365 -> 64.685604 | J15: =J40/J22*365 -> 67.094427 | K15: =K40/K22*365 -> 64.911818 | L15: =L40/L22*365 -> 69.434214 | M15: =AVERAGE(H15:L15) -> 66.459978 | N15: =M15 -> 66.459978 | O15: =N15 -> 66.459978 | P15: =O15 -> 66.459978 | Q15: =P15 -> 66.459978
D16: Days Inventory Outstanding | H16: =H41/-H23*365 -> 241.26061 | I16: =I41/-I23*365 -> 262.4264 | J16: =J41/-J23*365 -> 193.96362 | K16: =K41/-K23*365 -> 196.72202 | L16: =L41/-L23*365 -> 223.89199 | M16: =AVERAGE(H16:L16) -> 223.65293 | N16: =M16 -> 223.65293 | O16: =N16 -> 223.65293 | P16: =O16 -> 223.65293 | Q16: =P16 -> 223.65293
D17: Days Payables Outstanding | H17: =H53/-H23*365 -> 111.57328 | I17: =I53/-I23*365 -> 102.45311 | J17: =J53/-J23*365 -> 86.660386 | K17: =K53/-K23*365 -> 129.22602 | L17: =L53/-L23*365 -> 140.91648 | M17: =AVERAGE(H17:L17) -> 114.16585 | N17: =M17 -> 114.16585 | O17: =N17 -> 114.16585 | P17: =O17 -> 114.16585 | Q17: =P17 -> 114.16585
D18: Capital Asset Turnover Ratio | H18: =H22/SUM(H44:H45) -> 3.1764324 | I18: =I22/SUM(I44:I45) -> 3.7469134 | J18: =J22/SUM(J44:J45) -> 4.4734699 | K18: =K22/SUM(K44:K45) -> 4.8449214 | L18: =L22/SUM(L44:L45) -> 4.3544993 | M18: =AVERAGE(H18:L18) -> 4.1192473 | N18: =M18 -> 4.1192473 | O18: =N18 -> 4.1192473 | P18: =O18 -> 4.1192473 | Q18: =P18 -> 4.1192473
A20: INCOME STATEMENT
D22: Revenue | H22: ='Historical Data'!H5 -> 88650.1 | I22: ='Historical Data'!I5 -> 106341.9 | J22: ='Historical Data'!J5 -> 115992.6 | K22: ='Historical Data'!K5 -> 126675.8 | L22: ='Historical Data'!L5 -> 129645.2 | M22: =L22*(1+M7) -> 142799.78 | N22: =M22*(1+N7) -> 155840.16 | O22: =N22*(1+O7) -> 168648.26 | P22: =O22*(1+P7) -> 181122.95 | Q22: =P22*(1+Q7) -> 193180.64
D23: Less: Cost of Good Sold | H23: =-SUM('Historical Data'!H9:H11) -> -34984.6 | I23: =-SUM('Historical Data'!I9:I11) -> -41802.9 | J23: =-SUM('Historical Data'!J9:J11) -> -49068.4 | K23: =-SUM('Historical Data'!K9:K11) -> -49375.8 | L23: =-SUM('Historical Data'!L9:L11) -> -47642.6 | M23: =-M22*M8 -> -56206.897 | N23: =-N22*N8 -> -61339.675 | O23: =-O22*O8 -> -66381.026 | P23: =-P22*P8 -> -71291.143 | Q23: =-Q22*Q8 -> -76037.124
D24: Gross Profit | H24: =SUM(H22:H23) -> 53665.5 | I24: =SUM(I22:I23) -> 64539 | J24: =SUM(J22:J23) -> 66924.2 | K24: =SUM(K22:K23) -> 77300 | L24: =SUM(L22:L23) -> 82002.6 | M24: =SUM(M22:M23) -> 86592.878 | N24: =SUM(N22:N23) -> 94500.485 | O24: =SUM(O22:O23) -> 102267.24 | ... Q24: =SUM(Q22:Q23) -> 117143.51
D25: Less: Operating Expenses | H25: =-SUM('Historical Data'!H12,'Historical Data'!H15) -> -34241.6 | I25: =-SUM('Historical Data'!I12,'Historical Data'!I15) -> -44009.8 | J25: =-SUM('Historical Data'!J12,'Historical Data'!J15) -> -50829.7 | K25: =-SUM('Historical Data'!K12,'Historical Data'!K15) -> -54845.1 | L25: =-SUM('Historical Data'!L12,'Historical Data'!L15) -> -56881.1 | M25: =M22*-M9 -> -60262.172 | N25: =N22*-N9 -> -65765.275 | O25: =O22*-O9 -> -71170.354 | P25: =P22*-P9 -> -76434.732 | Q25: =Q22*-Q9 -> -81523.131
D26: EBITDA | H26: =SUM(H24:H25) -> 19423.9 | I26: =SUM(I24:I25) -> 20529.2 | J26: =SUM(J24:J25) -> 16094.5 | K26: =SUM(K24:K25) -> 22454.9 | L26: =SUM(L24:L25) -> 25121.5 | M26: =SUM(M24:M25) -> 26330.706 | N26: =SUM(N24:N25) -> 28735.21 | O26: =SUM(O24:O25) -> 31096.883 | ... Q26: =SUM(Q24:Q25) -> 35620.383
D27: Less: Depreciation & Amortization | H27: =-'Historical Data'!H14 -> -2745.8 | I27: =-'Historical Data'!I14 -> -3039.6 | J27: =-'Historical Data'!J14 -> -3104.2 | K27: =-'Historical Data'!K14 -> -2993 | L27: =-'Historical Data'!L14 -> -3571.6 | M27: =M109 -> -3332.3855 | N27: =N109 -> -3316.8339 | O27: =O109 -> -3299.9201 | P27: =P109 -> -3278.5879 | Q27: =Q109 -> -3250.584
D28: EBIT | H28: =SUM(H26:H27) -> 16678.1 | I28: =SUM(I26:I27) -> 17489.6 | J28: =SUM(J26:J27) -> 12990.3 | K28: =SUM(K26:K27) -> 19461.9 | L28: =SUM(L26:L27) -> 21549.9 | M28: =SUM(M26:M27) -> 22998.321 | N28: =SUM(N26:N27) -> 25418.376 | O28: =SUM(O26:O27) -> 27796.963 | ... Q28: =SUM(Q26:Q27) -> 32369.799
D29: Less: Interest | H29: =-'Historical Data'!H13 -> -589.2 | I29: =-'Historical Data'!I13 -> -523.7 | J29: =-'Historical Data'!J13 -> -1073.6 | K29: =-'Historical Data'!K13 -> -1124.1 | L29: =-'Historical Data'!L13 -> -1217 | M29: =M116 -> -819.58351 | N29: =N116 -> -765.40043 | O29: =O116 -> -711.21735 | P29: =P116 -> -657.03426 | Q29: =Q116 -> -602.85118
D30: Other Income | H30: ='Historical Data'!H6+'Historical Data'!H18 -> 2332.1 | I30: ='Historical Data'!I6+'Historical Data'!I18 -> 1476.9 | J30: ='Historical Data'!J6+'Historical Data'!J18 -> 1131 | K30: ='Historical Data'!K6+'Historical Data'!K18 -> 1893.5 | L30: ='Historical Data'!L6+'Historical Data'!L18 -> 4937.4 | M30: =M22*M12 -> 2941.0238 | N30: =N22*N12 -> 3209.5962 | O30: =O22*O12 -> 3473.3847 | P30: =P22*P12 -> 3730.3064 | Q30: =Q22*Q12 -> 3978.6397
D31: Profit Before Tax | H31: =SUM(H28:H30) -> 18421 | I31: =SUM(I28:I30) -> 18442.8 | J31: =SUM(J28:J30) -> 13047.7 | K31: =SUM(K28:K30) -> 20231.3 | L31: =SUM(L28:L30) -> 25270.3 | M31: =SUM(M28:M30) -> 25119.761 | N31: =SUM(N28:N30) -> 27862.572 | O31: =SUM(O28:O30) -> 30559.13 | ... Q31: =SUM(Q28:Q30) -> 35745.587
D32: Less: Taxes | H32: =-'Historical Data'!H22 -> -2243.3 | I32: =-'Historical Data'!I22 -> -1639.6 | J32: =-'Historical Data'!J22 -> -2979.6 | K32: =-'Historical Data'!K22 -> -2116.7 | L32: =-'Historical Data'!L22 -> -3110.3 | M32: =M31*-M13 -> -3349.7188 | N32: =N31*-N13 -> -3715.4725 | O32: =O31*-O13 -> -4075.0584 | P32: =P31*-P13 -> -4426.1198 | Q32: =Q31*-Q13 -> -4766.6722
D33: Profit After Tax | H33: =SUM(H31:H32) -> 16177.7 | I33: =SUM(I31:I32) -> 16803.2 | J33: =SUM(J31:J32) -> 10068.1 | K33: =SUM(K31:K32) -> 18114.6 | L33: =SUM(L31:L32) -> 22160 | M33: =SUM(M31:M32) -> 21770.042 | N33: =SUM(N31:N32) -> 24147.099 | O33: =SUM(O31:O32) -> 26484.072 | ... Q33: =SUM(Q31:Q32) -> 30978.915
A35: BALANCE SHEET
B37: ASSET'S
C38: Current Assets
D39: Cash & Bank | H39: ='Historical Data'!H50+'Historical Data'!H51 -> 19904.5 | I39: ='Historical Data'!I50+'Historical Data'!I51 -> 25785.8 | J39: ='Historical Data'!J50+'Historical Data'!J51 -> 26168.9 | K39: ='Historical Data'!K50+'Historical Data'!K51 -> 15793.5 | L39: ='Historical Data'!L50+'Historical Data'!L51 -> 15630.8 | M39: =M95 -> 22683.804 | N39: =N95 -> 34862.331 | O39: =O95 -> 48781.233 | P39: =P95 -> 64452.328 | Q39: =Q95 -> 81866.656
D40: Accounts Receivable | H40: ='Historical Data'!H49 -> 16072.1 | I40: ='Historical Data'!I49 -> 18846 | J40: ='Historical Data'!J49 -> 21321.8 | K40: ='Historical Data'!K49 -> 22528.1 | L40: ='Historical Data'!L49 -> 24662.5 | M40: =M22/365*M15 -> 26001.287 | N40: =N22/365*N15 -> 28375.709 | O40: =O22/365*O15 -> 30707.835 | P40: =P22/365*P15 -> 32979.254 | Q40: =Q22/365*Q15 -> 35174.742
D41: Inventory | H41: ='Historical Data'!H46 -> 23124.4 | I41: ='Historical Data'!I46 -> 30055.3 | J41: ='Historical Data'!J46 -> 26075.3 | K41: ='Historical Data'!K46 -> 26611.8 | L41: ='Historical Data'!L46 -> 29224.1 | M41: =-M23/365*M16 -> 34440.65 | N41: =-N23/365*N16 -> 37585.748 | O41: =-O23/365*O16 -> 40674.824 | P41: =-P23/365*P16 -> 43683.487 | Q41: =-Q23/365*Q16 -> 46591.577
D42: Other Current Assets | H42: =SUM('Historical Data'!H48,'Historical Data'!H54,'Historical Data'!H53,'Historical Data'!H52,'Historical Data'!H56) -> 10187.2 | I42: =SUM('Historical Data'!I48,'Historical Data'!I54,'Historical Data'!I53,'Historical Data'!I52,'Historical Data'!I56) -> 9667.2 | J42: =SUM('Historical Data'!J48,'Historical Data'!J54,'Historical Data'!J53,'Historical Data'!J52,'Historical Data'!J56) -> 13730.8 | K42: =SUM('Historical Data'!K48,'Historical Data'!K54,'Historical Data'!K53,'Historical Data'!K52,'Historical Data'!K56) -> 39182.4 | L42: =SUM('Historical Data'!L48,'Historical Data'!L54,'Historical Data'!L53,'Historical Data'!L52,'Historical Data'!L56) -> 39940.8 | M42: =L42 -> 39940.8 | N42: =M42 -> 39940.8 | O42: =N42 -> 39940.8 | P42: =O42 -> 39940.8 | Q42: =P42 -> 39940.8
C43: Non-Current Assets
D44: Plant, Property & Equipment | H44: =SUM('Historical Data'!H30:'Historical Data'!H32) -> 26272.1 | I44: =SUM('Historical Data'!I30:'Historical Data'!I32) -> 26265.8 | J44: =SUM('Historical Data'!J30:'Historical Data'!J32) -> 25135.2 | K44: =SUM('Historical Data'!K30:'Historical Data'!K32) -> 25570.3 | L44: =SUM('Historical Data'!L30:'Historical Data'!L32) -> 28627 | M44: =M110-M45 -> 28488.056 | N44: =N110-N45 -> 28336.943 | O44: =O110-O45 -> 28146.353 | P44: =P110-P45 -> 27896.156 | Q44: =Q110-Q45 -> 27572.729
D45: Intangible Assets | H45: ='Historical Data'!H34+'Historical Data'!H35 -> 1636.6 | I45: ='Historical Data'!I34+'Historical Data'!I35 -> 2115.4 | J45: ='Historical Data'!J34+'Historical Data'!J35 -> 793.8 | K45: ='Historical Data'!K34+'Historical Data'!K35 -> 575.8 | L45: ='Historical Data'!L34+'Historical Data'!L35 -> 1145.7 | M45: =L45 -> 1145.7 | N45: =M45 -> 1145.7 | O45: =N45 -> 1145.7 | P45: =O45 -> 1145.7 | Q45: =P45 -> 1145.7
D46: Goodwill | H46: ='Historical Data'!H33 -> 3953.9 | I46: ='Historical Data'!I33 -> 4030.9 | J46: ='Historical Data'!J33 -> 4131.7 | K46: ='Historical Data'!K33 -> 4167.4 | L46: ='Historical Data'!L33 -> 4231.1 | M46: =L46 -> 4231.1 | N46: =M46 -> 4231.1 | O46: =N46 -> 4231.1 | P46: =O46 -> 4231.1 | Q46: =P46 -> 4231.1
...

Sheet Lease Liab
A1: Alkem Laboratories Limited
A2: Lease Liability
E5: Amount | F5: Duration | G5: Rate | H5: Repay
D6: Exim | E6: 800 | F6: 5 | G6: 0.085 | H6: =E6/F6 -> 160
D7: HSBC | E7: 1259.4 | F7: 5 | G7: 0.0549 | H7: =E7/F7 -> 251.88
D8: Citi | E8: 1205.2 | F8: 5 | G8: 0.0489 | H8: =E8/F8 -> 241.04
D9: OD | E9: 4242.3
D10: CC | E10: 3106.6
D11: Lease Liab | E11: 3195.5 | H11: 260
E12: =SUM(E6:E11) -> 13809 | H12: =SUM(H6:H11) -> 912.92

Sheet Scenarios
A1: Alkem Laboratories Limited
A2: Revenue Scenarios
D4: Scenarios | E4: Growth % | H4: =[1]Model!L2+1 -> 2026 | I4: =[1]Model!M2+1 -> 2027 | J4: =[1]Model!N2+1 -> 2028 | K4: =[1]Model!O2+1 -> 2029 | L4: =[1]Model!P2+1 -> 2030
D5: Base Case | E5: =AVERAGE(Model!I7:L7) -> 0.10146596 | H5: =E5 -> 0.10146596 | I5: =H5*(1-$E$8) -> 0.091319368 | J5: =I5*(1-$E$8) -> 0.082187431 | K5: =J5*(1-$E$8) -> 0.073968688 | L5: =K5*(1-$E$8) -> 0.066571819
D6: Bull Case | E6: =MAX(Model!I7:L7) -> 0.19956887 | H6: =E6 -> 0.19956887 | I6: =H6*(1-$E$8) -> 0.17961198 | J6: =I6*(1-$E$8) -> 0.16165078 | K6: =J6*(1-$E$8) -> 0.1454857 | L6: =K6*(1-$E$8) -> 0.13093713
D7: Bear Case | E7: =MIN(Model!I7:L7) -> 0.023440941 | H7: =E7 -> 0.023440941 | I7: =H7*(1-$E$8) -> 0.021096847 | J7: =I7*(1-$E$8) -> 0.018987163 | K7: =J7*(1-$E$8) -> 0.017088446 | L7: =K7*(1-$E$8) -> 0.015379602
D8: Annual growth tapering | E8: =10% -> 0.1

Sheet WACC
A1: Alkem Laboratories Limited
A2: Weighted-Average Cost of Capital (WACC)
A3: All Amounts Denominated in INR MM Unless Otherwise Stated
A5: Comparable Companies Beta
H8: Equity | I8: Total | J8: Debt/ | K8: Debt/ | L8: Tax | M8: Levered | N8: Unlevered
D9: Company Name | H9: Value | I9: Debt | J9: Equity | K9: Capital | L9: Rate % | M9: Beta | N9: Beta
D10: Dr. Reddy's Laboratories Limited | H10: =Comps!N8 -> 1134356 | I10: =Comps!L8 -> 46770 | J10: =I10/H10 -> 0.041230443 | K10: =I10/(H10+I10) -> 0.039597808 | L10: 0.3 | M10: 0.26 | N10: =M10/(1+J10*(1+K10)) -> 0.24931365
D11: Zydus Lifesciences Limited | H11: =Comps!N9 -> 1066200 | I11: =Comps!L9 -> 32130 | J11: =I11/H11 -> 0.030135059 | K11: =I11/(H11+I11) -> 0.029253503 | L11: =L10 -> 0.3 | M11: 0.4 | N11: =M11/(1+J11*(1+K11)) -> 0.38796659
D12: Torrent Pharmaceuticals Limited | H12: =Comps!N10 -> 1578482 | I12: =Comps!L10 -> 32020 | J12: =I12/H12 -> 0.020285312 | K12: =I12/(H12+I12) -> 0.019882 | L12: =L11 -> 0.3 | M12: 0.14 | N12: =M12/(1+J12*(1+K12)) -> 0.1371623
D13: Mankind Pharma Limited | H13: =Comps!N11 -> 1043740 | I13: =Comps!L11 -> 85110 | J13: =I13/H13 -> 0.081543296 | K13: =I13/(H13+I13) -> 0.075395314 | L13: =L12 -> 0.3 | M13: 0.45 | N13: =M13/(1+J13*(1+K13)) -> 0.41372033
D14: Lupin Limited | H14: =Comps!N12 -> 1033390 | I14: =Comps!L12 -> 54480 | J14: =I14/H14 -> 0.05271969 | K14: =I14/(H14+I14) -> 0.050079513 | L14: =L13 -> 0.3 | M14: 0.18 | N14: =M14/(1+J14*(1+K14)) -> 0.17055794
D15: Aurobindo Pharma Limited | H15: =Comps!N13 -> 843550 | I15: =Comps!L13 -> 82630 | J15: =I15/H15 -> 0.097955071 | K15: =I15/(H15+I15) -> 0.089215919 | L15: =L14 -> 0.3 | M15: 0.02 | N15: =M15/(1+J15*(1+K15)) -> 0.018071839
D16: Abbott India Limited | H16: =Comps!N14 -> 538403 | I16: =Comps!L14 -> 1970 | J16: =I16/H16 -> 0.0036589692 | K16: =I16/(H16+I16) -> 0.00364563 | L16: =L15 -> 0.3 | M16: 0.02 | N16: =M16/(1+J16*(1+K16)) -> 0.019926823
D17: GlaxoSmithKline Pharmaceuticals Limited | H17: =Comps!N15 -> 339336 | I17: =Comps!L15 -> 100 | J17: =I17/H17 -> 0.00029469317 | K17: =I17/(H17+I17) -> 0.00029460635 | L17: =L16 -> 0.3 | M17: 0.05 | N17: =M17/(1+J17*(1+K17)) -> 0.049985265
D18: Ipca Laboratories Limited | H18: =Comps!N16 -> 416530 | I18: =Comps!L16 -> 13630 | J18: =I18/H18 -> 0.032722733 | K18: =I18/(H18+I18) -> 0.031685884 | L18: =L17 -> 0.3 | M18: 0.05 | N18: =M18/(1+J18*(1+K18)) -> 0.048367145
D19: Gland Pharma Limited | H19: =Comps!N17 -> 376160 | I19: =Comps!L17 -> 3140 | J19: =I19/H19 -> 0.0083475117 | K19: =I19/(H19+I19) -> 0.0082784076 | L19: =L18 -> 0.3 | M19: 0.49 | N19: =M19/(1+J19*(1+K19)) -> 0.48591028
D20: Average | J20: =AVERAGE(J10:J19) -> 0.036889278 | K20: =AVERAGE(K10:K19) -> 0.034732858 | L20: =AVERAGE(L10:L19) -> 0.3 | M20: =AVERAGE(M10:M19) -> 0.206 | N20: =AVERAGE(N10:N19) -> 0.19809822
D21: Median | J21: =MEDIAN(J10:J19) -> 0.031428896 | K21: =MEDIAN(K10:K19) -> 0.030469694 | L21: =MEDIAN(L10:L19) -> 0.3 | M21: =MEDIAN(M10:M19) -> 0.16 | N21: =MEDIAN(N10:N19) -> 0.15386012
D23: Alkem Pharma | H23: =Comps!K23 -> 654960 | I23: =Comps!L23 -> 13810
D25: WACC Calculation
C27: Target Capital Structure
D29: Proportion of Debt | I29: =K20 -> 0.034732858
D30: Proportion of Equity | I30: =1-I29 -> 0.96526714
C32: Current Capital Structure
D33: Market Cap | I33: =H23 -> 654960
D34: Total Debt | I34: =I23 -> 13810
D35: Debt / Equity | I35: =I34/I33 -> 0.021085257
C37: Current Capital Structure
D38: Pre-Tax Cost of Debt | I38: =Model!M11 -> 0.059351402
D39: Tax Rate | I39: =Model!M13 -> 0.13334995
D40: After-Tax Cost of Debt | I40: =I38*(1-I39) -> 0.051436896
C42: Cost of Equity
D43: Risk Free Rate | I43: 0.065
D44: Equity Market Return | I44: =Market_Data!I8 -> 0.13038872
D45: Equity Risk Premium | I45: =I44-I43 -> 0.065388717
D46: Levered Equity Beta | I46: =N21*(1+I35)*(1-I39) -> 0.13615445
D47: Cost of Equity | I47: =I43+I46*I45 -> 0.073902965
D49: WACC | I49: =(I29*I40)+(I47*I30) -> 0.073122654

Sheet Market_Data
A1: Alkem Laboratories Limited
A2: Market Data
E4: Index
D5: Date | E5: Close Price
D6: 46230 | E6: 23995.95 | G6: Periods (yrs) | I6: 9
D7: 46227 | E7: 23767.45
D8: 46226 | E8: 23869.6 | G8: Return's | I8: =_xlfn.RRI(I6,E2622,E6) -> 0.13038872
D9: 46225 | E9: 23996.25
D10: 46224 | E10: 24187.7
D11: 46223 | E11: 24238.5
D12: 46220 | E12: 24334.3
D13: 46219 | E13: 24072.75
D14: 46218 | E14: 24078.5
D15: 46217 | E15: 24052.05
D16: 46216 | E16: 24211
D17: 46213 | E17: 24206.9
D18: 46212 | E18: 23962.8
D19: 46211 | E19: 23882.05
D20: 46210 | E20: 24398.7
... D2622: 42370 | E2622: 7963.2

Sheet Comps
A1: Alkem Laboratories Limited
A2: Comps Valuation
I5: Market Data | P5: Financial Data | T5: Valuation
I6: Price | J6: Shares | K6: Market Cap | L6: Debt | M6: Cash | N6: EV | P6: Sales | Q6: EBITDA | R6: Earnings | T6: EV/Sales | U6: EV/EBITDA | V6: P/E
D7: Company Name | G7: Ticker | I7: (₹/share) | J7: M | K7: ₹ MM | M7: & Equivalents | N7: ₹ MM | P7: ₹ MM | Q7: ₹ MM | R7: ₹ MM | T7: x | U7: x | V7: x
D8: Dr. Reddy's Laboratories Limited | G8: DRREDDY | I8: =Comps_Data!I7 -> 1328 | J8: =Comps_Data!J7 -> 830 | K8: =I8*J8 -> 1102240 | L8: =Comps_Data!K7 -> 46770 | M8: =Comps_Data!L7 -> 14654 | N8: =K8+L8-M8 -> 1134356 | P8: =Comps_Data!M7 -> 325535 | Q8: =Comps_Data!N7 -> 92133 | R8: =Comps_Data!O7 -> 56544 | T8: =N8/P8 -> 3.48459 | U8: =N8/Q8 -> 12.312157 | V8: =K8/R8 -> 19.493492
D9: Zydus Lifesciences Limited | G9: ZYDUSLIFE | I9: =Comps_Data!I8 -> 1104 | J9: =Comps_Data!J8 -> 1010 | K9: =I9*J9 -> 1115040 | L9: =Comps_Data!K8 -> 32130 | M9: =Comps_Data!L8 -> 80970 | N9: =K9+L9-M9 -> 1066200 | P9: =Comps_Data!M8 -> 232420 | Q9: =Comps_Data!N8 -> 70580 | R9: =Comps_Data!O8 -> 46730 | T9: =N9/P9 -> 4.5873849 | U9: =N9/Q9 -> 15.106262 | V9: =K9/R9 -> 23.861331
D10: Torrent Pharmaceuticals Limited | G10: TORNTPHARM | I10: =Comps_Data!I9 -> 4604 | J10: =Comps_Data!J9 -> 338 | K10: =I10*J10 -> 1556152 | L10: =Comps_Data!K9 -> 32020 | M10: =Comps_Data!L9 -> 9690 | N10: =K10+L10-M10 -> 1578482 | P10: =Comps_Data!M9 -> 115160 | Q10: =Comps_Data!N9 -> 37210 | R10: =Comps_Data!O9 -> 19110 | T10: =N10/P10 -> 13.70686 | U10: =N10/Q10 -> 42.420908 | V10: =K10/R10 -> 81.431293
D11: Mankind Pharma Limited | G11: MANKIND | I11: =Comps_Data!I10 -> 2393 | J11: =Comps_Data!J10 -> 410 | K11: =I11*J11 -> 981130 | L11: =Comps_Data!K10 -> 85110 | M11: =Comps_Data!L10 -> 22500 | N11: =K11+L11-M11 -> 1043740 | P11: =Comps_Data!M10 -> 122070 | Q11: =Comps_Data!N10 -> 30260 | R11: =Comps_Data!O10 -> 20110 | T11: =N11/P11 -> 8.55034 | U11: =N11/Q11 -> 34.492399 | V11: =K11/R11 -> 48.788165
D12: Lupin Limited | G12: LUPIN | I12: =Comps_Data!I11 -> 2278 | J12: =Comps_Data!J11 -> 455 | K12: =I12*J12 -> 1036490 | L12: =Comps_Data!K11 -> 54480 | M12: =Comps_Data!L11 -> 57580 | N12: =K12+L12-M12 -> 1033390 | P12: =Comps_Data!M11 -> 227080 | Q12: =Comps_Data!N11 -> 54792 | R12: =Comps_Data!O11 -> 33060 | T12: =N12/P12 -> 4.5507751 | U12: =N12/Q12 -> 18.860235 | V12: =K12/R12 -> 31.351785
D13: Aurobindo Pharma Limited | G13: AUROPHARMA | I13: =Comps_Data!I12 -> 1454 | J13: =Comps_Data!J12 -> 580 | K13: =I13*J13 -> 843320 | L13: =Comps_Data!K12 -> 82630 | M13: =Comps_Data!L12 -> 82400 | N13: =K13+L13-M13 -> 843550 | P13: =Comps_Data!M12 -> 317240 | Q13: =Comps_Data!N12 -> 65510 | R13: =Comps_Data!O12 -> 34840 | T13: =N13/P13 -> 2.6590279 | U13: =N13/Q13 -> 12.87666 | V13: =K13/R13 -> 24.205511
D14: Abbott India Limited | G14: ABBOTINDIA | I14: =Comps_Data!I13 -> 26073 | J14: =Comps_Data!J13 -> 21 | K14: =I14*J14 -> 547533 | L14: =Comps_Data!K13 -> 1970 | M14: =Comps_Data!L13 -> 11100 | N14: =K14+L14-M14 -> 538403 | P14: =Comps_Data!M13 -> 64090 | Q14: =Comps_Data!N13 -> 16950 | R14: =Comps_Data!O13 -> 14140 | T14: =N14/P14 -> 8.4007333 | U14: =N14/Q14 -> 31.764189 | V14: =K14/R14 -> 38.722277
D15: GlaxoSmithKline Pharmaceuticals Limited | G15: GLAXO | I15: =Comps_Data!I14 -> 2174 | J15: =Comps_Data!J14 -> 169 | K15: =I15*J15 -> 367406 | L15: =Comps_Data!K14 -> 100 | M15: =Comps_Data!L14 -> 28170 | N15: =K15+L15-M15 -> 339336 | P15: =Comps_Data!M14 -> 37490 | Q15: =Comps_Data!N14 -> 11790 | R15: =Comps_Data!O14 -> 9280 | T15: =N15/P15 -> 9.0513737 | U15: =N15/Q15 -> 28.781679 | V15: =K15/R15 -> 39.591164
D16: Ipca Laboratories Limited | G16: IPCALAB | I16: =Comps_Data!I15 -> 1656 | J16: =Comps_Data!J15 -> 250 | K16: =I16*J16 -> 414000 | L16: =Comps_Data!K15 -> 13630 | M16: =Comps_Data!L15 -> 11100 | N16: =K16+L16-M16 -> 416530 | P16: =Comps_Data!M15 -> 88970 | Q16: =Comps_Data!N15 -> 17310 | R16: =Comps_Data!O15 -> 7850 | T16: =N16/P16 -> 4.6816905 | U16: =N16/Q16 -> 24.062969 | V16: =K16/R16 -> 52.738854
D17: Gland Pharma Limited | G17: GLAND | I17: =Comps_Data!I16 -> 2522 | J17: =Comps_Data!J16 -> 160 | K17: =I17*J17 -> 403520 | L17: =Comps_Data!K16 -> 3140 | M17: =Comps_Data!L16 -> 30500 | N17: =K17+L17-M17 -> 376160 | P17: =Comps_Data!M16 -> 56160 | Q17: =Comps_Data!N16 -> 12690 | R17: =Comps_Data!O16 -> 6990 | T17: =N17/P17 -> 6.6980057 | U17: =N17/Q17 -> 29.642238 | V17: =K17/R17 -> 57.728183
D20: Average | T20: =AVERAGE(T8:T17) -> 6.6370781 | U20: =AVERAGE(U8:U17) -> 25.03197 | V20: =AVERAGE(V8:V17) -> 41.791205
D21: Median | T21: =MEDIAN(T8:T17) -> 5.6898481 | U21: =MEDIAN(U8:U17) -> 26.422324 | V21: =MEDIAN(V8:V17) -> 39.156721
D23: Alkem Laboratories Limited | H23: ALKEM | I23: =Comps_Data!I5 -> 5458 | J23: =Comps_Data!J5 -> 120 | K23: =I23*J23 -> 654960 | L23: =Comps_Data!K5 -> 13810 | M23: =Comps_Data!L5 -> 18810 | N23: =K23+L23-M23 -> 649960 | P23: =Comps_Data!M5 -> 129650 | Q23: =Comps_Data!N5 -> 25120 | R23: =Comps_Data!O5 -> 22150
D25: Metric | E25: Comps | H25: EV | I25: Net Debt | J25: Equity Value | K25: Shares | L25: Share Price
D26: EV/Revenue | E26: =T21 -> 5.6898481 | H26: =E26*P23 -> 737688.8 | I26: =$L$23-$M$23 -> -5000 | J26: =H26-I26 -> 742688.8 | K26: =J23 -> 120 | L26: =J26/K26 -> 6189.0734
D27: Ev/EBITDA | E27: =U21 -> 26.422324 | H27: =E27*Q23 -> 663728.79 | I27: =$L$23-$M$23 -> -5000 | J27: =H27-I27 -> 668728.79 | K27: =K26 -> 120 | L27: =J27/K27 -> 5572.7399
D28: PE | E28: =V21 -> 39.156721 | H28: =E28*R23 -> 867321.36 | I28: =$L$23-$M$23 -> -5000 | J28: =H28-I28 -> 872321.36 | K28: =K27 -> 120 | L28: =J28/K28 -> 7269.3447

Sheet Comps_Data
A1: Alkem Laboratories Limited
A2: Comps Data
D4: Company | H4: Ticker | I4: Price | J4: Shares | K4: Debt | L4: Cash | M4: Sales | N4: EBITDA | O4: Net Income
D5: Alkem Laboratories Limited | H5: ALKEM | I5: 5458 | J5: 120 | K5: 13810 | L5: 18810 | M5: 129650 | N5: 25120 | O5: 22150
D7: Dr. Reddy's Laboratories Limited | H7: DRREDDY | I7: 1328 | J7: 830 | K7: 46770 | L7: 14654 | M7: 325535 | N7: 92133 | O7: 56544
D8: Zydus Lifesciences Limited | H8: ZYDUSLIFE | I8: 1104 | J8: 1010 | K8: 32130 | L8: 80970 | M8: 232420 | N8: 70580 | O8: 46730
D9: Torrent Pharmaceuticals Limited | H9: TORNTPHARM | I9: 4604 | J9: 338 | K9: 32020 | L9: 9690 | M9: 115160 | N9: 37210 | O9: 19110
D10: Mankind Pharma Limited | H10: MANKIND | I10: 2393 | J10: 410 | K10: 85110 | L10: 22500 | M10: 122070 | N10: 30260 | O10: 20110
D11: Lupin Limited | H11: LUPIN | I11: 2278 | J11: 455 | K11: 54480 | L11: 57580 | M11: 227080 | N11: 54792 | O11: 33060
D12: Aurobindo Pharma Limited | H12: AUROPHARMA | I12: 1454 | J12: 580 | K12: 82630 | L12: 82400 | M12: 317240 | N12: 65510 | O12: 34840
D13: Abbott India Limited | H13: ABBOTINDIA | I13: 26073 | J13: 21 | K13: 1970 | L13: 11100 | M13: 64090 | N13: 16950 | O13: 14140
D14: GlaxoSmithKline Pharmaceuticals Limited | H14: GLAXO | I14: 2174 | J14: 169 | K14: 100 | L14: 28170 | M14: 37490 | N14: 11790 | O14: 9280
D15: Ipca Laboratories Limited | H15: IPCALAB | I15: 1656 | J15: 250 | K15: 13630 | L15: 11100 | M15: 88970 | N15: 17310 | O15: 7850
D16: Gland Pharma Limited | H16: GLAND | I16: 2522 | J16: 160 | K16: 3140 | L16: 30500 | M16: 56160 | N16: 12690 | O16: 6990
C18: Source: www.screener.in

Sheet Foot_Ball Field
A1: Alkem Laboratories Limited
A2: Football Field Chart
A4: Football Field Chart
E6: Comps | F6: DCF | G6: 52-week high/low | H6: Market Consensus
D7: High | E7: =MAX(Comps!L26:L28) -> 7269.3447 | F7: 8152.17 | G7: 4738.5 | H7: =H8 -> 5840
D8: High | E8: =E7 -> 7269.3447 | F8: =F7 -> 8152.17 | G8: =G7 -> 4738.5 | H8: 5840 | I8: ( Motilal Oswal )
D9: Low | E9: =MIN(Comps!L26:L28) -> 5572.7399 | F9: 5606.58 | G9: 5933.5 | H9: 6500 | I9: ( ICICI Securities)
D10: Low | E10: =E9 -> 5572.7399 | F10: =F9 -> 5606.58 | G10: =G9 -> 5933.5 | H10: 6500
A12: Valuation Summary
