Workbook

Sheet Historical Data
A1: NETFLIX, INC.
A2: Historical Data
H4: 2021 | I4: =H4+1 -> 2022 | J4: =I4+1 -> 2023 | K4: =J4+1 -> 2024 | L4: =K4+1 -> 2025
C5: Revenues | H5: 29697844 | I5: 31615550 | J5: 33723297 | K5: 39000966 | L5: 45183036
D6: Cost of revenues | H6: 17332683 | I6: 19168285 | J6: 19715368 | K6: 21038464 | L6: 23275329
D7: Marketing / Sales and marketing | H7: 2545146 | I7: 2530502 | J7: 2657883 | K7: 2917554 | L7: 3301306
D8: Technology and development | H8: 2273885 | I8: 2711041 | J8: 2675758 | K8: 2925295 | L8: 3391390
D9: General and administrative | H9: 1351621 | I9: 1572891 | J9: 1720285 | K9: 1702039 | L9: 1888408
C10: Operating income | H10: =H5-H6-H7-H8-H9 -> 6194509 | I10: =I5-I6-I7-I8-I9 -> 5632831 | J10: =J5-J6-J7-J8-J9 -> 6954003 | K10: =K5-K6-K7-K8-K9 -> 10417614 | L10: =L5-L6-L7-L8-L9 -> 13326603
D12: Other income (expense):
D13: Interest expense | H13: -765620 | I13: -706212 | J13: -699826 | K13: -718733 | L13: -776510
D14: Interest and other income (expense) | H14: 411214 | I14: 337310 | J14: -48772 | K14: 266776 | L14: 172459
D15: Income before income taxes | H15: =H10+H13+H14 -> 5840103 | I15: =I10+I13+I14 -> 5263929 | J15: =J10+J13+J14 -> 6205405 | K15: =K10+K13+K14 -> 9965657 | L15: =L10+L13+L14 -> 12722552
D16: Provision for income taxes | H16: -723875 | I16: -772005 | J16: -797415 | K16: -1254026 | L16: -1741351
C17: Net income | H17: =H15+H16 -> 5116228 | I17: =I15+I16 -> 4491924 | J17: =J15+J16 -> 5407990 | K17: =K15+K16 -> 8711631 | L17: =L15+L16 -> 10981201
A19: BALANCE SHEET
B20: Assets
C21: Current assets:
D22: Cash and cash equivalents | H22: 6027804 | I22: 5147176 | J22: 7116913 | K22: 7804733 | L22: 9033681
D23: Short-term investments | H23: 0 | I23: 911276 | J23: 20973 | K23: 1779006 | L23: 28678
D24: Other current assets | H24: 2042021 | I24: 3208021 | J24: 2780247 | K24: 3516640 | L24: 3957832
C25: Total current assets | H25: =SUM(H22:H24) -> 8069825 | I25: =SUM(I22:I24) -> 9266473 | J25: =SUM(J22:J24) -> 9918133 | K25: =SUM(K22:K24) -> 13100379 | L25: =SUM(L22:L24) -> 13020191
D27: Content assets, net | H27: 30919539 | I27: 32736713 | J27: 31658056 | K27: 32452462 | L27: 32778392
D28: Property and equipment, net | H28: 1323453 | I28: 1398257 | J28: 1491444 | K28: 1593756 | L28: 2004350
D29: Other non-current assets | H29: 4271846 | I29: 5193325 | J29: 5664359 | K29: 6483777 | L29: 7794060
C30: Total assets | H30: =H25+H27+H28+H29 -> 44584663 | I30: =I25+I27+I28+I29 -> 48594768 | J30: =J25+J27+J28+J29 -> 48731992 | K30: =K25+K27+K28+K29 -> 53630374 | L30: =L25+L27+L28+L29 -> 55596993
A32: Liabilities and Stockholders' Equity
B33: Current liabilities:
D34: Current content liabilities | H34: 4292967 | I34: 4480150 | J34: 4466470 | K34: 4393681 | L34: 4084854
D35: Accounts payable | H35: 837483 | I35: 671513 | J35: 747412 | K35: 899909 | L35: 900612
D36: Accrued expenses and other liabilities | H36: 1449351 | I36: 1514650 | J36: 1803960 | K36: 2156544 | L36: 3220869
D37: Deferred revenue | H37: 1209342 | I37: 1264661 | J37: 1442969 | K37: 1520813 | L37: 1775730
D38: Short-term debt | H38: 699823 | I38: 0 | J38: 399844 | K38: 1784453 | L38: 998865
C39: Total current liabilities | H39: =SUM(H34:H38) -> 8488966 | I39: =SUM(I34:I38) -> 7930974 | J39: =SUM(J34:J38) -> 8860655 | K39: =SUM(K34:K38) -> 10755400 | L39: =SUM(L34:L38) -> 10980930
D41: Non-current content liabilities | H41: 3094213 | I41: 3081277 | J41: 2578173 | K41: 1780806 | L41: 1579476
D42: Long-term debt | H42: 14693072 | I42: 14353076 | J42: 14143417 | K42: 13798351 | L42: 13463971
D43: Other non-current liabilities | H43: 2459164 | I43: 2452040 | J43: 2561434 | K43: 2552250 | L43: 2957128
C44: Total liabilities | H44: =H39+H41+H42+H43 -> 28735415 | I44: =I39+I41+I42+I43 -> 27817367 | J44: =J39+J41+J42+J43 -> 28143679 | K44: =K39+K41+K42+K43 -> 28886807 | L44: =L39+L41+L42+L43 -> 28981505
A46: Stockholders' equity:
D47: Preferred stock ($0.001 par; none issued/outstanding) | H47: 0 | I47: 0 | J47: 0 | K47: 0 | L47: 0
...

Sheet Model
A1: NETFLIX, INC. | H1: Historical Data | M1: Forecasted Period
A2: Financial Statement Analysis & Valuation | H2: 2021 | I2: =H2+1 -> 2022 | J2: =I2+1 -> 2023 | K2: =J2+1 -> 2024 | L2: =K2+1 -> 2025 | M2: =L2+1 -> 2026 | N2: =M2+1 -> 2027 | O2: =N2+1 -> 2028 | P2: =O2+1 -> 2029 | Q2: =P2+1 -> 2030
A4: Ratios & Assumptions
C6: LIVE SCENARIO | E6: Base Case | G6: =IF(E6=Scenario!D6,1,IF(E6=Scenario!D7,2,3)) -> 1
C7: Revenue Growth % | I7: =(I22-H22)/H22 -> 0.064573913 | J7: =(J22-I22)/I22 -> 0.066668048 | K7: =(K22-J22)/J22 -> 0.1564992 | L7: =(L22-K22)/K22 -> 0.15851069 | M7: {=CHOOSE(G6,Scenario!H6:L6,Scenario!H7:L7,Scenario!H8:L8)} -> 0.11156296 | N7: 0.10435891 | O7: 0.097620043 | P7: 0.091316334 | Q7: 0.085419681
C8: COGS as % of Revenue | H8: =H23/-H22 -> 0.58363439 | I8: =I23/-I22 -> 0.60629295 | J8: =J23/-J22 -> 0.5846216 | K8: =K23/-K22 -> 0.53943443 | L8: =L23/-L22 -> 0.51513424 | M8: =AVERAGE(H8:L8) -> 0.56582352 | N8: =M8 -> 0.56582352 | O8: =N8 -> 0.56582352 | P8: =O8 -> 0.56582352 | Q8: =P8 -> 0.56582352
C9: Operating Expense as % of Revenue | H9: =H25/-H22 -> 0.20778114 | I9: =I25/-I22 -> 0.21554058 | J9: =J25/-J22 -> 0.20917071 | K9: =K25/-K22 -> 0.19345387 | L9: =L25/-L22 -> 0.18991871 | M9: =AVERAGE(H9:L9) -> 0.203173 | N9: =M9 -> 0.203173 | O9: =N9 -> 0.203173 | P9: =O9 -> 0.203173 | Q9: =P9 -> 0.203173
C10: Depreciation & Amortization as % PP&E | H10: =H27/-H45 -> 0.15747594 | I10: =I27/-I45 -> 0.24078692 | J10: =J27/-J45 -> 0.2393298 | K10: =K27/-K45 -> 0.20637663 | L10: =L27/-L45 -> 0.16633273 | M10: =AVERAGE(H10:L10) -> 0.2020604 | N10: =M10 -> 0.2020604 | O10: =N10 -> 0.2020604 | P10: =O10 -> 0.2020604 | Q10: =P10 -> 0.2020604
C11: Interest as % of Debt | H11: =H29/-H58 -> 0.049738532 | I11: =I29/-I58 -> 0.049202833 | J11: =J29/-J58 -> 0.048120294 | K11: =K29/-K58 -> 0.04612347 | L11: =L29/-L58 -> 0.053690023 | M11: =AVERAGE(H11:L11) -> 0.049375031 | N11: =M11 -> 0.049375031 | O11: =N11 -> 0.049375031 | P11: =O11 -> 0.049375031 | Q11: =P11 -> 0.049375031
C12: Other Revenue as % of Revenue | H12: =H30/H22 -> 0.013846594 | I12: =I30/I22 -> 0.010669117 | J12: =J30/J22 -> -0.0014462406 | K12: =K30/K22 -> 0.0068402408 | L12: =L30/L22 -> 0.0038168971 | M12: =AVERAGE(H12:L12) -> 0.0067453217 | N12: =M12 -> 0.0067453217 | O12: =N12 -> 0.0067453217 | P12: =O12 -> 0.0067453217 | Q12: =P12 -> 0.0067453217
C13: Dividend Payout Ratio | H13: =H90/H33 -> 0 | I13: =I90/I33 -> 0 | J13: =J90/J33 -> 0 | K13: =K90/K33 -> 0 | L13: =L90/L33 -> 0 | M13: =AVERAGE(H13:L13) -> 0 | N13: =M13 -> 0 | O13: =N13 -> 0 | P13: =O13 -> 0 | Q13: =P13 -> 0
C14: Day Sale's Oustanding | H14: 0 | I14: =H14 -> 0 | J14: =I14 -> 0 | K14: =J14 -> 0 | L14: =K14 -> 0 | M14: =L14 -> 0 | N14: =M14 -> 0 | O14: =N14 -> 0 | P14: =O14 -> 0 | Q14: =P14 -> 0
C15: Day Inventory Outstanding | H15: 0 | I15: =H15 -> 0 | J15: =I15 -> 0 | K15: =J15 -> 0 | L15: =K15 -> 0 | M15: =L15 -> 0 | N15: =M15 -> 0 | O15: =N15 -> 0 | P15: =O15 -> 0 | Q15: =P15 -> 0
C16: Day Payable Oustanding | H16: =H54/-H23*365 -> 17.636121 | I16: =I54/-I23*365 -> 12.786864 | J16: =J54/-J23*365 -> 13.837194 | K16: =K54/-K23*365 -> 15.612679 | L16: =L54/-L23*365 -> 14.123254 | M16: =AVERAGE(H16:L16) -> 14.799222 | N16: =M16 -> 14.799222 | O16: =N16 -> 14.799222 | P16: =O16 -> 14.799222 | Q16: =P16 -> 14.799222
C17: Capital Assets Turnover Ratio | H17: =H22/(H45) -> 22.439667 | I17: =I22/(I45) -> 22.610686 | J17: =J22/(J45) -> 22.611172 | K17: =K22/(K45) -> 24.471102 | L17: =L22/(L45) -> 22.542488 | M17: =AVERAGE(H17:L17) -> 22.935023 | N17: =M17 -> 22.935023 | O17: =N17 -> 22.935023 | P17: =O17 -> 22.935023 | Q17: =P17 -> 22.935023
C18: Tax Rate (% of PBT) | H18: =-H32/H31 -> 0.12853599 | I18: =-I32/I31 -> 0.1566808 | J18: =-J32/J31 -> 0.1363462 | K18: =-K32/K31 -> 0.13012965 | L18: =-L32/L31 -> 0.14055437 | M18: =AVERAGE(H18:L18) -> 0.1384494 | N18: =M18 -> 0.1384494 | O18: =N18 -> 0.1384494 | P18: =O18 -> 0.1384494 | Q18: =P18 -> 0.1384494
A20: INCOME STATEMENT
B22: Revenue | H22: ='Historical Data'!H5 -> 29697844 | I22: ='Historical Data'!I5 -> 31615550 | J22: ='Historical Data'!J5 -> 33723297 | K22: ='Historical Data'!K5 -> 39000966 | L22: ='Historical Data'!L5 -> 45183036 | M22: =L22*(1+M7) -> 50223789 | N22: =M22*(1+N7) -> 55465089 | O22: =N22*(1+O7) -> 60879593 | P22: =O22*(1+P7) -> 66438895 | Q22: =P22*(1+Q7) -> 72114084
B23: Less: Cost of Good Sold | H23: =-'Historical Data'!H6 -> -17332683 | I23: =-'Historical Data'!I6 -> -19168285 | J23: =-'Historical Data'!J6 -> -19715368 | K23: =-'Historical Data'!K6 -> -21038464 | L23: =-'Historical Data'!L6 -> -23275329 | M23: =M22*-M8 -> -28417801 | N23: =N22*-N8 -> -31383452 | O23: =O22*-O8 -> -34447106 | P23: =P22*-P8 -> -37592689 | Q23: =Q22*-Q8 -> -40803845
B24: Gross Profit | H24: =SUM(H22:H23) -> 12365161 | I24: =SUM(I22:I23) -> 12447265 | J24: =SUM(J22:J23) -> 14007929 | K24: =SUM(K22:K23) -> 17962502 | L24: =SUM(L22:L23) -> 21907707 | M24: =SUM(M22:M23) -> 21805988 | N24: =SUM(N22:N23) -> 24081637 | O24: =SUM(O22:O23) -> 26432487 | ... Q24: =SUM(Q22:Q23) -> 31310239
B25: Less: Operating Expense | H25: =-SUM('Historical Data'!H7:H9) -> -6170652 | I25: =-SUM('Historical Data'!I7:I9) -> -6814434 | J25: =-SUM('Historical Data'!J7:J9) -> -7053926 | K25: =-SUM('Historical Data'!K7:K9) -> -7544888 | L25: =-SUM('Historical Data'!L7:L9) -> -8581104 | M25: =M22*-M9 -> -10204118 | N25: =N22*-N9 -> -11269009 | O25: =O22*-O9 -> -12369090 | P25: =P22*-P9 -> -13498590 | Q25: =Q22*-Q9 -> -14651635
B26: EBITDA | H26: =SUM(H24:H25) -> 6194509 | I26: =SUM(I24:I25) -> 5632831 | J26: =SUM(J24:J25) -> 6954003 | K26: =SUM(K24:K25) -> 10417614 | L26: =SUM(L24:L25) -> 13326603 | M26: =SUM(M24:M25) -> 11601870 | N26: =SUM(N24:N25) -> 12812628 | O26: =SUM(O24:O25) -> 14063397 | ... Q26: =SUM(Q24:Q25) -> 16658604
B27: Less: Depreciation & Amortization | H27: =-'Historical Data'!H62 -> -208412 | I27: =-'Historical Data'!I62 -> -336682 | J27: =-'Historical Data'!J62 -> -356947 | K27: =-'Historical Data'!K62 -> -328914 | L27: =-'Historical Data'!L62 -> -333389 | M27: =M111 -> -404999.77 | N27: =N111 -> -367575.02 | O27: =O111 -> -339479.16 | P27: =P111 -> -318586.32 | Q27: =Q111 -> -303190.78
B28: EBIT | H28: =SUM(H26:H27) -> 5986097 | I28: =SUM(I26:I27) -> 5296149 | J28: =SUM(J26:J27) -> 6597056 | K28: =SUM(K26:K27) -> 10088700 | L28: =SUM(L26:L27) -> 12993214 | M28: =SUM(M26:M27) -> 11196870 | N28: =SUM(N26:N27) -> 12445053 | O28: =SUM(O26:O27) -> 13723918 | ... Q28: =SUM(Q26:Q27) -> 16355413
B29: Less: Interest | H29: ='Historical Data'!H13 -> -765620 | I29: ='Historical Data'!I13 -> -706212 | J29: ='Historical Data'!J13 -> -699826 | K29: ='Historical Data'!K13 -> -718733 | L29: ='Historical Data'!L13 -> -776510 | M29: =M118 -> -714102.97 | N29: =N118 -> -714017.03 | O29: =O118 -> -713931.1 | P29: =P118 -> -713845.16 | Q29: =Q118 -> -713759.22
B30: Other Income | H30: ='Historical Data'!H14 -> 411214 | I30: ='Historical Data'!I14 -> 337310 | J30: ='Historical Data'!J14 -> -48772 | K30: ='Historical Data'!K14 -> 266776 | L30: ='Historical Data'!L14 -> 172459 | M30: =M22*M12 -> 338775.62 | N30: =N22*N12 -> 374129.87 | O30: =O22*O12 -> 410652.44 | P30: =P22*P12 -> 448151.72 | Q30: =Q22*Q12 -> 486432.7
B31: Profit Before Tax | H31: =SUM(H28:H30) -> 5631691 | I31: =SUM(I28:I30) -> 4927247 | J31: =SUM(J28:J30) -> 5848458 | K31: =SUM(K28:K30) -> 9636743 | L31: =SUM(L28:L30) -> 12389163 | M31: =SUM(M28:M30) -> 10821543 | N31: =SUM(N28:N30) -> 12105166 | O31: =SUM(O28:O30) -> 13420640 | ... Q31: =SUM(Q28:Q30) -> 16128087
B32: Less: Tax | H32: ='Historical Data'!H16 -> -723875 | I32: ='Historical Data'!I16 -> -772005 | J32: ='Historical Data'!J16 -> -797415 | K32: ='Historical Data'!K16 -> -1254026 | L32: ='Historical Data'!L16 -> -1741351 | M32: =-M31*M18 -> -1498236.1 | N32: =-N31*N18 -> -1675953 | O32: =-O31*O18 -> -1858079.5 | P32: =-P31*P18 -> -2043975 | Q32: =-Q31*Q18 -> -2232923.9
B33: Profit After Tax | H33: =SUM(H31:H32) -> 4907816 | I33: =SUM(I31:I32) -> 4155242 | J33: =SUM(J31:J32) -> 5051043 | K33: =SUM(K31:K32) -> 8382717 | L33: =SUM(L31:L32) -> 10647812 | M33: =SUM(M31:M32) -> 9323306.5 | N33: =SUM(N31:N32) -> 10429213 | O33: =SUM(O31:O32) -> 11562560 | ... Q33: =SUM(Q31:Q32) -> 13895163
A35: BALANCE SHEET
A37: Assets
B38: Current Assets
C39: Cash & Bank | H39: ='Historical Data'!H22 -> 6027804 | I39: ='Historical Data'!I22 -> 5147176 | J39: ='Historical Data'!J22 -> 7116913 | K39: ='Historical Data'!K22 -> 7804733 | L39: ='Historical Data'!L22 -> 9033681 | M39: =M97 -> 18792074 | N39: =N97 -> 29478838 | O39: =O97 -> 41267275 | P39: =P97 -> 54188628 | Q39: =Q97 -> 68267993
C40: Trade Receivable | H40: 0 | I40: =H40 -> 0 | J40: =I40 -> 0 | K40: =J40 -> 0 | L40: =K40 -> 0 | M40: =L40 -> 0 | N40: =M40 -> 0 | O40: =N40 -> 0 | P40: =O40 -> 0 | Q40: =P40 -> 0
C41: Inventories | H41: 0 | I41: =H41 -> 0 | J41: =I41 -> 0 | K41: =J41 -> 0 | L41: =K41 -> 0 | M41: =L41 -> 0 | N41: =M41 -> 0 | O41: =N41 -> 0 | P41: =O41 -> 0 | Q41: =P41 -> 0
C42: Other Current Assets | H42: ='Historical Data'!H24+'Historical Data'!H23 -> 2042021 | I42: ='Historical Data'!I24+'Historical Data'!I23 -> 4119297 | J42: ='Historical Data'!J24+'Historical Data'!J23 -> 2801220 | K42: ='Historical Data'!K24+'Historical Data'!K23 -> 5295646 | L42: ='Historical Data'!L24+'Historical Data'!L23 -> 3986510 | M42: =L42 -> 3986510 | N42: =M42 -> 3986510 | O42: =N42 -> 3986510 | P42: =O42 -> 3986510 | Q42: =P42 -> 3986510
B44: Non-Current Assets
C45: Plant, Property & Equipment | H45: ='Historical Data'!H28 -> 1323453 | I45: ='Historical Data'!I28 -> 1398257 | J45: ='Historical Data'!J28 -> 1491444 | K45: ='Historical Data'!K28 -> 1593756 | L45: ='Historical Data'!L28 -> 2004350 | M45: =M112 -> 1819134.3 | N45: =N112 -> 1680087.5 | O45: =O112 -> 1576688.5 | P45: =P112 -> 1500495.7 | Q45: =Q112 -> 1444751.4
C46: Content Assets | H46: ='Historical Data'!H27 -> 30919539 | I46: ='Historical Data'!I27 -> 32736713 | J46: ='Historical Data'!J27 -> 31658056 | K46: ='Historical Data'!K27 -> 32452462 | L46: ='Historical Data'!L27 -> 32778392 | M46: =L46 -> 32778392 | N46: =M46 -> 32778392 | O46: =N46 -> 32778392 | P46: =O46 -> 32778392 | Q46: =P46 -> 32778392
C47: Goodwill | H47: 0 | I47: =H47 -> 0 | J47: =I47 -> 0 | K47: =J47 -> 0 | L47: =K47 -> 0 | M47: =L47 -> 0 | N47: =M47 -> 0 | O47: =N47 -> 0 | P47: =O47 -> 0 | Q47: =P47 -> 0
...

Sheet Re-Payment
A1: NETFLIX, INC.
A2: Loan Repayment
D4: UNSECURED — SENIOR NOTES (fixed rate, publicly registered) | H4: 2026 | I4: =H4+1 -> 2027 | J4: =I4+1 -> 2028 | K4: =J4+1 -> 2029 | L4: =K4+1 -> 2030 | M4: =L4+1 -> 2031 | N4: =M4+1 -> 2032 | O4: =N4+1 -> 2033 | P4: =O4+1 -> 2034 | Q4: =P4+1 -> 2035
D5: 4.375% Senior Notes (issued Oct 2016, matures Nov 2026) | H5: 1000 | I5: 0 | J5: 0 | K5: 0 | L5: 0 | M5: 0 | N5: 0 | O5: 0 | P5: 0 | Q5: 0
D6: 3.625% Senior Notes (issued May 2017, matures May 2027) | H6: 0 | I6: 1526 | J6: 0 | K6: 0 | L6: 0 | M6: 0 | N6: 0 | O6: 0 | P6: 0 | Q6: 0
D7: 4.875% Senior Notes (issued Oct 2017, matures Apr 2028) | H7: 0 | I7: 0 | J7: 1600 | K7: 0 | L7: 0 | M7: 0 | N7: 0 | O7: 0 | P7: 0 | Q7: 0
D8: 5.875% Senior Notes (issued Apr 2018, matures Nov 2028) | H8: 0 | I8: 0 | J8: 1900 | K8: 0 | L8: 0 | M8: 0 | N8: 0 | O8: 0 | P8: 0 | Q8: 0
D9: 4.625% Senior Notes (issued Oct 2018, matures May 2029) | H9: 0 | I9: 0 | J9: 0 | K9: 1292 | L9: 0 | M9: 0 | N9: 0 | O9: 0 | P9: 0 | Q9: 0
D10: 6.375% Senior Notes (issued Oct 2018, matures May 2029) | H10: 0 | I10: 0 | J10: 0 | K10: 800 | L10: 0 | M10: 0 | N10: 0 | O10: 0 | P10: 0 | Q10: 0
D11: 3.875% Senior Notes (issued Apr 2019, matures Nov 2029) | H11: 0 | I11: 0 | J11: 0 | K11: 1409 | L11: 0 | M11: 0 | N11: 0 | O11: 0 | P11: 0 | Q11: 0
D12: 5.375% Senior Notes (issued Apr 2019, matures Nov 2029) | H12: 0 | I12: 0 | J12: 0 | K12: 900 | L12: 0 | M12: 0 | N12: 0 | O12: 0 | P12: 0 | Q12: 0
D13: 3.625% Senior Notes (issued Oct 2019, matures June 2030) | H13: 0 | I13: 0 | J13: 0 | K13: 0 | L13: 1292 | M13: 0 | N13: 0 | O13: 0 | P13: 0 | Q13: 0
D14: 4.875% Senior Notes (issued Oct 2019, matures June 2030) | H14: 0 | I14: 0 | J14: 0 | K14: 0 | L14: 1000 | M14: 0 | N14: 0 | O14: 0 | P14: 0 | Q14: 0
D15: 4.900% Senior Notes (issued Aug 2024, matures Aug 2034) | H15: 0 | I15: 0 | J15: 0 | K15: 0 | L15: 0 | M15: 0 | N15: 0 | O15: 0 | P15: 1000 | Q15: 0
D16: 5.400% Senior Notes (issued Aug 2024, matures Aug 2054) | H16: 0 | I16: 0 | J16: 0 | K16: 0 | L16: 0 | M16: 0 | N16: 0 | O16: 0 | P16: 0 | Q16: 800
D17: OPERATING LEASE LIABILITIES (undiscounted future payments)
D18: Operating lease payments due | H18: 555.684 | I18: 481.542 | J18: 422.982 | K18: 351.107 | L18: 292.154 | M18: 0 | N18: 0 | O18: 0 | P18: 0 | Q18: 782.47
D19: TOTAL REPAYMENT | H19: =H5+H6+H7+H8+H9+H10+H11+H12+H13+H14+H15+H16+H18 -> 1555.684 | I19: =I5+I6+I7+I8+I9+I10+I11+I12+I13+I14+I15+I16+I18 -> 2007.542 | J19: =J5+J6+J7+J8+J9+J10+J11+J12+J13+J14+J15+J16+J18 -> 3922.982 | K19: =K5+K6+K7+K8+K9+K10+K11+K12+K13+K14+K15+K16+K18 -> 4752.107 | L19: =L5+L6+L7+L8+L9+L10+L11+L12+L13+L14+L15+L16+L18 -> 2584.154 | M19: =M5+M6+M7+M8+M9+M10+M11+M12+M13+M14+M15+M16+M18 -> 0 | N19: =N5+N6+N7+N8+N9+N10+N11+N12+N13+N14+N15+N16+N18 -> 0 | O19: =O5+O6+O7+O8+O9+O10+O11+O12+O13+O14+O15+O16+O18 -> 0 | ... Q19: =Q5+Q6+Q7+Q8+Q9+Q10+Q11+Q12+Q13+Q14+Q15+Q16+Q18 -> 1582.47

Sheet Scenario
A1: NETFLIX, INC.
A2: Live Scenario
D5: Scenarios | E5: Growth % | H5: =Model!M2 -> 2026 | I5: =Model!N2 -> 2027 | J5: =Model!O2 -> 2028 | K5: =Model!P2 -> 2029 | L5: =Model!Q2 -> 2030
D6: Base Case | E6: =AVERAGE(Model!I7:L7) -> 0.11156296 | H6: =E6 -> 0.11156296 | I6: =H6*(1-$E$8) -> 0.10435891 | J6: =I6*(1-$E$8) -> 0.097620043 | K6: =J6*(1-$E$8) -> 0.091316334 | L6: =K6*(1-$E$8) -> 0.085419681
D7: Bull Case | E7: =MAX(Model!I7:L7) -> 0.15851069 | H7: =E7 -> 0.15851069 | I7: =H7*(1-$E$8) -> 0.14827503 | J7: =I7*(1-$E$8) -> 0.13870033 | K7: =J7*(1-$E$8) -> 0.12974391 | L7: =K7*(1-$E$8) -> 0.12136584
D8: Bear Case | E8: =MIN(Model!I7:L7) -> 0.064573913 | H8: =E8 -> 0.064573913 | I8: =H8*(1-$E$8) -> 0.060404123 | J8: =I8*(1-$E$8) -> 0.056503592 | K8: =J8*(1-$E$8) -> 0.052854934 | L8: =K8*(1-$E$8) -> 0.049441884
D9: Annual growth tapering | E9: =10% -> 0.1

Sheet WACC
A1: NETFLIX, INC.
A2: Weighted-Average Cost of Capital (WACC)
A3: All Amounts in $ Millions Unless Otherwise Stated
A5: Comparable Companies Beta
H7: Equity | I7: Total | J7: Debt/ | K7: Debt/ | L7: Tax | M7: Levered | N7: Unlevered
D8: Company Name | H8: Value | I8: Debt | J8: Equity | K8: Capital | L8: Rate % | M8: Beta | N8: Beta
D9: The Walt Disney Company | H9: =Comps!K8 -> 194698.3 | I9: =Comps!L8 -> 42030 | J9: =I9/H9 -> 0.21587245 | K9: =I9/(H9+I9) -> 0.17754531 | L9: 0.21 | M9: 1.44 | N9: =M9/(1+J9*(1+K9)) -> 1.1481426
D10: Comcast Corporation | H10: =Comps!K9 -> 127688.4 | I10: =Comps!L9 -> 99090 | J10: =I10/H10 -> 0.77602977 | K10: =I10/(H10+I10) -> 0.43694638 | L10: =L9 -> 0.21 | M10: 1 | N10: =M10/(1+J10*(1+K10)) -> 0.47278794
D11: Paramount Skydance Corporation | H11: =Comps!K10 -> 17307.227 | I11: =Comps!L10 -> 14520 | J11: =I11/H11 -> 0.83895587 | K11: =I11/(H11+I11) -> 0.45621316 | L11: =L10 -> 0.21 | M11: 1.26 | N11: =M11/(1+J11*(1+K11)) -> 0.56713364
D12: Fox Corporation | H12: =Comps!K11 -> 32762.772 | I12: =Comps!L11 -> 6600 | J12: =I12/H12 -> 0.20144816 | K12: =I12/(H12+I12) -> 0.16767112 | L12: =L11 -> 0.21 | M12: 0.5 | N12: =M12/(1+J12*(1+K12)) -> 0.40478449
D13: Average | J13: =AVERAGE(J9:J12) -> 0.50807656 | K13: =AVERAGE(K9:K12) -> 0.30959399 | L13: =AVERAGE(L9:L12) -> 0.21 | M13: =AVERAGE(M9:M12) -> 1.05 | N13: =AVERAGE(N9:N12) -> 0.64821217
D14: Median | J14: =MEDIAN(J9:J12) -> 0.49595111 | K14: =MEDIAN(K9:K12) -> 0.30724584 | L14: =MEDIAN(L9:L12) -> 0.21 | M14: =MEDIAN(M9:M12) -> 1.13 | N14: =MEDIAN(N9:N12) -> 0.51996079
D16: Netflix, Inc. | H16: =Comps!K16 -> 324370.93 | I16: =Comps!L16 -> 14462.836
A18: WACC Calculation
C20: Target Capital Structure
D21: Proportion of Debt | I21: =Comps!L16/(Comps!K16+Comps!L16) -> 0.042684164
D22: Proportion of Equity | I22: =1-I21 -> 0.95731584
C24: Current Capital Structure
D25: Market Cap | I25: =H16 -> 324370.93
D26: Total Debt | I26: =I16 -> 14462.836
D27: Debt / Equity | I27: =I26/I25 -> 0.044587338
C29: Cost of Debt
D30: Pre-Tax Cost of Debt | I30: =-'Historical Data'!L13/('Historical Data'!L38+'Historical Data'!L42) -> 0.053690023
D31: Tax Rate | I31: =Model!M18 -> 0.1384494
D32: After-Tax Cost of Debt | I32: =I30*(1-I31) -> 0.046256672
C34: Cost of Equity
D35: Risk Free Rate | I35: 0.05
D36: Equity Risk Premium | I36: ='Market Data'!J9 -> 0.17353366
D37: Levered Equity Beta (relevered to NFLX capital structure) | I37: =N14*(1+I27)*(1-I31) -> 0.46794643
D38: Cost of Equity | I38: =I35+I37*I36 -> 0.13120446
D40: WACC | I40: =(I21*I32)+(I38*I22) -> 0.12757853

Sheet Market Data
A1: NETFLIX, INC.
A2: Market Data ( Nasdaq)
F5: Index (Nasdaq)
E6: DATE | F6: Closing Price
E7: 46280 | F7: 25981.57 | I7: Period (yrs) | J7: 10
E8: 46279 | F8: 26186.41
E9: 46276 | F9: 26333.04 | I9: Return's | J9: =_xlfn.RRI(J7,F2518,F7) -> 0.17353366
E10: 46275 | F10: 26081.72
E11: 46274 | F11: 26253.34
E12: 46273 | F12: 26421.41
E13: 46269 | F13: 26506.99
E14: 46268 | F14: 26584.06
E15: 46267 | F15: 26217.83
E16: 46266 | F16: 26099.77
E17: 46265 | F17: 26370.89
E18: 46262 | F18: 26402.42
E19: 46261 | F19: 26541.35
E20: 46260 | F20: 26130.2
E21: 46259 | F21: 26151.3
... E2518: 42629 | F2518: 5244.57

Sheet Comps Data
A1: NETFLIX, INC.
A2: Comps Data
D4: Company | H4: Ticker | I4: Price | J4: Shares | K4: Debt | L4: Cash | M4: Sales | N4: EBITDA | O4: Net Income
D5: Netflix, Inc. | H5: NFLX | I5: 77.9 | J5: 4163.94 | K5: =Model!L58/1000 -> 14462.836 | L5: =Model!L39/1000 -> 9033.681 | M5: =Model!L22/1000 -> 45183.036 | N5: =Model!L26/1000 -> 13326.603 | O5: =Model!L33/1000 -> 10647.812
D7: The Walt Disney Company | H7: DIS | I7: 108.77 | J7: 1790 | K7: 42030 | L7: 5700 | M7: 94420 | N7: 19210 | O7: 12400
D8: Comcast Corporation | H8: CMCSA | I8: 33.78 | J8: 3780 | K8: 99090 | L8: 7320 | M8: 123730 | N8: 38100 | O8: 16190
D9: Paramount Skydance Corporation | H9: PSKY | I9: 25.67 | J9: 674.22 | K9: 14520 | L9: 2740 | M9: 28760 | N9: 15670 | O9: -14
D10: Fox Corporation | H10: FOXA | I10: 73.8 | J10: 443.94 | K10: 6600 | L10: 4370 | M10: 16470 | N10: 3650 | O10: 2040
D12: (marketscreener.com)

Sheet Comps
A1: NETFLIX, INC.
A2: Comps Valuation
I5: Market Data | P5: Financial Data | T5: Valuation
I6: Price | J6: Shares | K6: Market Cap | L6: Debt | M6: Cash | N6: EV | P6: Sales | Q6: EBITDA | R6: Earnings | T6: EV/Sales | U6: EV/EBITDA | V6: PE
D7: Company Name | G7: Ticker | I7: ($/share) | J7: M | K7: $M | M7: & Equivalents | N7: $M | P7: $M | Q7: $M | R7: $M | T7: x | U7: x | V7: x
D8: The Walt Disney Company | G8: DIS | I8: ='Comps Data'!I7 -> 108.77 | J8: ='Comps Data'!J7 -> 1790 | K8: =I8*J8 -> 194698.3 | L8: ='Comps Data'!K7 -> 42030 | M8: ='Comps Data'!L7 -> 5700 | N8: =K8+L8-M8 -> 231028.3 | P8: ='Comps Data'!M7 -> 94420 | Q8: ='Comps Data'!N7 -> 19210 | R8: ='Comps Data'!O7 -> 12400 | T8: =N8/P8 -> 2.4468153 | U8: =N8/Q8 -> 12.02646 | V8: =K8/R8 -> 15.701476
D9: Comcast Corporation | G9: CMCSA | I9: ='Comps Data'!I8 -> 33.78 | J9: ='Comps Data'!J8 -> 3780 | K9: =I9*J9 -> 127688.4 | L9: ='Comps Data'!K8 -> 99090 | M9: ='Comps Data'!L8 -> 7320 | N9: =K9+L9-M9 -> 219458.4 | P9: ='Comps Data'!M8 -> 123730 | Q9: ='Comps Data'!N8 -> 38100 | R9: ='Comps Data'!O8 -> 16190 | T9: =N9/P9 -> 1.7736879 | U9: =N9/Q9 -> 5.760063 | V9: =K9/R9 -> 7.8868684
D10: Paramount Skydance Corporation | G10: PSKY | I10: ='Comps Data'!I9 -> 25.67 | J10: ='Comps Data'!J9 -> 674.22 | K10: =I10*J10 -> 17307.227 | L10: ='Comps Data'!K9 -> 14520 | M10: ='Comps Data'!L9 -> 2740 | N10: =K10+L10-M10 -> 29087.227 | P10: ='Comps Data'!M9 -> 28760 | Q10: ='Comps Data'!N9 -> 15670 | R10: ='Comps Data'!O9 -> -14 | T10: =N10/P10 -> 1.0113779 | U10: =N10/Q10 -> 1.8562366 | V10: =K10/R10 -> -1236.2305
D11: Fox Corporation | G11: FOXA | I11: ='Comps Data'!I10 -> 73.8 | J11: ='Comps Data'!J10 -> 443.94 | K11: =I11*J11 -> 32762.772 | L11: ='Comps Data'!K10 -> 6600 | M11: ='Comps Data'!L10 -> 4370 | N11: =K11+L11-M11 -> 34992.772 | P11: ='Comps Data'!M10 -> 16470 | Q11: ='Comps Data'!N10 -> 3650 | R11: ='Comps Data'!O10 -> 2040 | T11: =N11/P11 -> 2.124637 | U11: =N11/Q11 -> 9.5870608 | V11: =K11/R11 -> 16.060182
D13: Average | T13: =AVERAGE(T8:T11) -> 1.8391295 | U13: =AVERAGE(U8:U11) -> 7.3074551 | V13: =AVERAGE(V8:V11) -> -299.1455
D14: Median | T14: =MEDIAN(T8:T11) -> 1.9491625 | U14: =MEDIAN(U8:U11) -> 7.6735619 | V14: =MEDIAN(V8:V11) -> 11.794172
D16: Netflix, Inc. | G16: NFLX | I16: ='Comps Data'!I5 -> 77.9 | J16: ='Comps Data'!J5 -> 4163.94 | K16: =I16*J16 -> 324370.93 | L16: ='Comps Data'!K5 -> 14462.836 | M16: ='Comps Data'!L5 -> 9033.681 | N16: =K16+L16-M16 -> 329800.08 | P16: ='Comps Data'!M5 -> 45183.036 | Q16: ='Comps Data'!N5 -> 13326.603 | R16: ='Comps Data'!O5 -> 10647.812
D18: Metric | E18: Comps | H18: EV | I18: Net Debt | J18: Equity Value | K18: Shares | L18: Share Price
D19: EV/Sales | E19: =T14 -> 1.9491625 | H19: =E19*P16 -> 88069.077 | I19: =$L$16-$M$16 -> 5429.155 | J19: =H19-I19 -> 82639.922 | K19: =J16 -> 4163.94 | L19: =J19/K19 -> 19.846569
D20: EV/EBITDA | E20: =U14 -> 7.6735619 | H20: =E20*Q16 -> 102262.51 | I20: =$L$16-$M$16 -> 5429.155 | J20: =H20-I20 -> 96833.358 | K20: =K19 -> 4163.94 | L20: =J20/K20 -> 23.255224
D21: P/E | E21: =V14 -> 11.794172 | H21: =E21*R16 -> 125582.13 | I21: =$L$16-$M$16 -> 5429.155 | J21: =H21-I21 -> 120152.97 | K21: =K20 -> 4163.94 | L21: =J21/K21 -> 28.855596

Sheet Foot Ball Field
A1: NETFLIX, INC.
A2: Valuation Summary — Football Field ($ per share)
A4: Football Field Data
E6: Comps | F6: DCF | G6: 52-week high/low | H6: Market Consensus
D7: High
D8: High
D9: Low
D10: Low
A12: Valuation Summary
