Workbook

Sheet Historical Data
A1: United Spirits Limited
A2: Historical Financial Data | L2: (Rs. In Crore)
H4: 2022 | I4: =H4+1 -> 2023 | J4: =I4+1 -> 2024 | K4: =J4+1 -> 2025 | L4: =K4+1 -> 2026
B5: INCOME
D6: Revenue from operations | H6: 31061.8 | I6: 27815.4 | J6: 26018 | K6: 27276 | L6: 27816
D7: Other income | H7: 35.5 | I7: 73.1 | J7: 225 | K7: 336 | L7: 478
D8: Total income | H8: 31097.3 | I8: 27888.5 | J8: 26243 | K8: 27612 | L8: 28294
B10: EXPENSES
D11: Cost of materials consumed | H11: 4796.9 | I11: 5337 | J11: 5254 | K11: 5443 | L11: 6007
D12: Purchase of stock-in-trade | H12: 577.3 | I12: 864.2 | J12: 675 | K12: 864 | L12: 808
D13: Change in inventories of finished goods, WIP & stock-in-trade | H13: -82.7 | I13: -137.1 | J13: 119 | K13: 90 | L13: -141
D14: Excise duty | H14: 21349.4 | I14: 17203.8 | J14: 14697 | K14: 15207 | L14: 15349
D15: Employee benefits expense | H15: 653.1 | I15: 610 | J15: 547 | K15: 609 | L15: 635
D16: Depreciation, amortisation and impairment expense | H16: 303.8 | I16: 282.5 | J16: 275 | K16: 283 | L16: 289
D17: Advertisement and sales promotion | H17: 694.9 | I17: 921.8 | J17: 1048 | K17: 1130 | L17: 1295
D18: Loss allowance on trade receivables & other financial assets (net) | H18: -12.9 | I18: -12
D19: Other expenses | H19: 1477.7 | I19: 1610.8 | J19: 1677 | K19: 1690 | L19: 1577
D20: Finance costs | H20: 88 | I20: 103.9 | J20: 76 | K20: 89 | L20: 158
D21: Total expenses | H21: 29845.5 | I21: 26784.9 | J21: 24368 | K21: 25405 | L21: 25977
B23: Profit before exceptional items, share of net profit/(loss) of associates/JVs and tax | H23: 1251.8 | I23: 1103.6 | J23: 1875 | K23: 2207 | L23: 2317
D24: Share of net profit/(loss) in associate / joint ventures | H24: 0 | I24: -1.4 | J24: -1 | K24: -7 | L24: -7
D25: Profit before exceptional items and tax | H25: 1251.8 | I25: 1102.2 | J25: 1874 | K25: 2200 | L25: 2310
D26: Add/(Less): Exceptional items (net) | H26: -165.2 | I26: 176.4 | J26: -17 | K26: -65 | L26: -91
D27: Profit before tax (continuing operations) | H27: 1086.6 | I27: 1278.6 | J27: 1857 | K27: 2135 | L27: 2219
D28: Tax expense:
D29: Current tax | H29: 259.3 | I29: 281.4 | J29: 450 | K29: 555 | L29: 637
D30: Current tax relating to earlier years | H30: -24.7 | I30: -115.9 | J30: -10 | K30: -11 | L30: 2
D31: Deferred tax (credit)/charge | H31: 41.4 | I31: -12.7 | J31: 9 | K31: 9 | L31: -129
D32: Total tax expense | H32: 276 | I32: 152.8 | J32: 449 | K32: 553 | L32: 510
B34: Profit for the year (continuing operations) | H34: 810.6 | I34: 1125.8 | J34: 1408 | K34: 1582 | L34: 1709
D35: Profit after tax from discontinued operations | L35: 129
D36: PROFIT FOR THE YEAR | H36: 810.6 | I36: 1125.8 | J36: 1408 | K36: 1582 | L36: 1838
D37: Other comprehensive income, net of tax | H37: 12.4 | I37: -2.2 | J37: -3 | K37: 0 | L37: 9
B38: TOTAL COMPREHENSIVE INCOME FOR THE YEAR | H38: 823 | I38: 1123.6 | J38: 1405 | K38: 1582 | L38: 1847
A40: BALANCE SHEET
B41: ASSETS
C42: Non-current assets
D43: Property, plant and equipment | H43: 1215.2 | I43: 978.3 | J43: 844 | K43: 850 | L43: 832
D44: Right-of-use assets | H44: 260.6 | I44: 172.6 | J44: 227 | K44: 457 | L44: 383
D45: Capital work-in-progress | H45: 87.7 | I45: 66.8 | J45: 37 | K45: 72 | L45: 77
...

Sheet Model
A1: United Spirits Limited | H1: Historical Period | M1: Forcasted Period
A2: Financial Statement Analysis & Valuation | H2: 2022 | I2: =H2+1 -> 2023 | J2: =I2+1 -> 2024 | K2: =J2+1 -> 2025 | L2: =K2+1 -> 2026 | M2: =L2+1 -> 2027 | N2: =M2+1 -> 2028 | O2: =N2+1 -> 2029 | P2: =O2+1 -> 2030 | Q2: =P2+1 -> 2031
A4: Ratios & Assumptions
C6: LIVE SCENARIO'S | E6: Base Case | H6: =IF(E6=Scenarios!D5,1,IF(E6=Scenarios!D6,2,3)) -> 1
D7: Revenue Growth % | I7: =I22/H22-1 -> -0.10451423 | J7: =J22/I22-1 -> -0.06461888 | K7: =K22/J22-1 -> 0.048351142 | L7: =L22/K22-1 -> 0.019797624 | M7: {=CHOOSE(H6,Scenarios!H5:L5,Scenarios!H6:L6,Scenarios!H7:L7)} -> -0.025246085 | N7: -0.022721477 | O7: -0.020449329 | P7: -0.018404396 | Q7: -0.016563957
D8: COGS as % of Revenue | H8: =-H23/H22 -> 0.17035394 | I8: =-I23/I22 -> 0.21801232 | J8: =-J23/J22 -> 0.23245445 | K8: =-K23/K22 -> 0.23452852 | L8: =-L23/L22 -> 0.23993385 | M8: =AVERAGE(H8:L8) -> 0.21905662 | N8: =M8 -> 0.21905662 | O8: =N8 -> 0.21905662 | P8: =O8 -> 0.21905662 | Q8: =P8 -> 0.21905662
D9: Operating Expense | H9: =-H25/H22 -> 0.77787507 | I9: =-I25/I22 -> 0.73104827 | J9: =-J25/J22 -> 0.69063725 | K9: =-K25/K22 -> 0.68323801 | L9: =-L25/L22 -> 0.67788323 | M9: =AVERAGE(H9:L9) -> 0.71213637 | N9: =M9 -> 0.71213637 | O9: =N9 -> 0.71213637 | P9: =O9 -> 0.71213637 | Q9: =P9 -> 0.71213637
D10: Deprication & Amortization as % PPE | H10: =-H27/(H45+H46) -> 0.18203607 | I10: =-I27/(I45+I46) -> 0.19925236 | J10: =-J27/(J45+J46) -> 0.22357724 | K10: =-K27/(K45+K46) -> 0.22621902 | L10: =-L27/(L45+L46) -> 0.29340102 | M10: =AVERAGE(H10:L10) -> 0.22489714 | N10: =M10 -> 0.22489714 | O10: =N10 -> 0.22489714 | P10: =O10 -> 0.22489714 | Q10: =P10 -> 0.22489714
D11: Interest as % of Debt | H11: =-H29/H58 -> 0.14535844 | I11: =-I29/I58 -> 0.56683033 | J11: =-J29/J58 -> 0.28679245 | K11: =-K29/K58 -> 0.18541667 | L11: =-L29/L58 -> 0.38256659 | M11: =AVERAGE(H11:L11) -> 0.3133929 | N11: =M11 -> 0.3133929 | O11: =N11 -> 0.3133929 | P11: =O11 -> 0.3133929 | Q11: =P11 -> 0.3133929
D12: Other Income as % Revenue | H12: =H30/H22 -> -0.0037763426 | I12: =I30/I22 -> 0.0088404265 | J12: =J30/J22 -> 0.0078407257 | K12: =K30/K22 -> 0.0096788385 | L12: =L30/L22 -> 0.018622376 | M12: =AVERAGE(H12:L12) -> 0.0082412047 | N12: =M12 -> 0.0082412047 | O12: =N12 -> 0.0082412047 | P12: =O12 -> 0.0082412047 | Q12: =P12 -> 0.0082412047
D13: Taxes as % of PBT | H13: =-H32/H31 -> 0.2511374 | I13: =-I32/I31 -> 0.11971169 | J13: =-J32/J31 -> 0.24217907 | K13: =-K32/K31 -> 0.25901639 | L13: =-L32/L31 -> 0.21637675 | M13: =AVERAGE(H13:L13) -> 0.21768426 | N13: =M13 -> 0.21768426 | O13: =N13 -> 0.21768426 | P13: =O13 -> 0.21768426 | Q13: =P13 -> 0.21768426
D14: Dividend Payout Ratio | H14: =-H90/H33 -> 0 | I14: =-I90/I33 -> 0 | J14: =-J90/J33 -> 0.20213523 | K14: =-K90/K33 -> 0.22439949 | L14: =-L90/L33 -> 0.68381159 | M14: =AVERAGE(H14:L14) -> 0.22206926 | N14: =M14 -> 0.22206926 | O14: =N14 -> 0.22206926 | P14: =O14 -> 0.22206926 | Q14: =P14 -> 0.22206926
D15: Day Sale's Outstanding | H15: =H40/H22*365 -> 27.891623 | I15: =I40/I22*365 -> 31.939501 | J15: =J40/J22*365 -> 42.871858 | K15: =K40/K22*365 -> 45.631691 | L15: =L40/L22*365 -> 47.357097 | M15: =AVERAGE(H15:L15) -> 39.138354 | N15: =M15 -> 39.138354 | O15: =N15 -> 39.138354 | P15: =O15 -> 39.138354 | Q15: =P15 -> 39.138354
D16: Day Inventory's Outstanding | H16: =-H41/H23*365 -> 148.76604 | I16: =-I41/I23*365 -> 134.22437 | J16: =-J41/J23*365 -> 124.50314 | K16: =-K41/K23*365 -> 131.51868 | L16: =-L41/L23*365 -> 145.9125 | M16: =AVERAGE(H16:L16) -> 136.98495 | N16: =M16 -> 136.98495 | O16: =N16 -> 136.98495 | P16: =O16 -> 136.98495 | Q16: =P16 -> 136.98495
D17: Day Payable's Outstanding | H17: =-H54/H23*365 -> 109.13096 | I17: =-I54/I23*365 -> 107.28921 | J17: =-J54/J23*365 -> 117.92493 | K17: =-K54/K23*365 -> 127.75285 | L17: =-L54/L23*365 -> 130.32589 | M17: =AVERAGE(H17:L17) -> 118.48477 | N17: =M17 -> 118.48477 | O17: =N17 -> 118.48477 | P17: =O17 -> 118.48477 | Q17: =P17 -> 118.48477
D18: Capital Assets Turnover Ratio | H18: =H22/(H45+H46) -> 18.61214 | I18: =I22/(I45+I46) -> 19.618705 | J18: =J22/(J45+J46) -> 21.152846 | K18: =K22/(K45+K46) -> 21.803357 | L18: =L22/(L45+L46) -> 28.239594 | M18: =AVERAGE(H18:L18) -> 21.885328 | N18: =M18 -> 21.885328 | O18: =N18 -> 21.885328 | P18: =O18 -> 21.885328 | Q18: =P18 -> 21.885328
A20: INCOME STATEMENT
C22: Revenue | H22: ='Historical Data'!H6 -> 31061.8 | I22: ='Historical Data'!I6 -> 27815.4 | J22: ='Historical Data'!J6 -> 26018 | K22: ='Historical Data'!K6 -> 27276 | L22: ='Historical Data'!L6 -> 27816 | M22: =L22*(1+M7) -> 27113.755 | N22: =M22*(1+N7) -> 26497.69 | O22: =N22*(1+O7) -> 25955.83 | P22: =O22*(1+P7) -> 25478.129 | Q22: =P22*(1+Q7) -> 25056.11
C23: Less: Cost Of Good Sold | H23: =-SUM('Historical Data'!H11:H13) -> -5291.5 | I23: =-SUM('Historical Data'!I11:I13) -> -6064.1 | J23: =-SUM('Historical Data'!J11:J13) -> -6048 | K23: =-SUM('Historical Data'!K11:K13) -> -6397 | L23: =-SUM('Historical Data'!L11:L13) -> -6674 | M23: =-M22*M8 -> -5939.4475 | N23: =-N22*N8 -> -5804.4944 | O23: =-O22*O8 -> -5685.7964 | P23: =-P22*P8 -> -5581.1528 | Q23: =-Q22*Q8 -> -5488.7068
C24: Gross Profit | H24: =SUM(H22:H23) -> 25770.3 | I24: =SUM(I22:I23) -> 21751.3 | J24: =SUM(J22:J23) -> 19970 | K24: =SUM(K22:K23) -> 20879 | L24: =SUM(L22:L23) -> 21142 | M24: =SUM(M22:M23) -> 21174.307 | N24: =SUM(N22:N23) -> 20693.196 | O24: =SUM(O22:O23) -> 20270.034 | ... Q24: =SUM(Q22:Q23) -> 19567.404
C25: Less: Operating Expense | H25: =-SUM('Historical Data'!H14:H15,'Historical Data'!H17:H19) -> -24162.2 | I25: =-SUM('Historical Data'!I14:I15,'Historical Data'!I17:I19) -> -20334.4 | J25: =-SUM('Historical Data'!J14:J15,'Historical Data'!J17:J19) -> -17969 | K25: =-SUM('Historical Data'!K14:K15,'Historical Data'!K17:K19) -> -18636 | L25: =-SUM('Historical Data'!L14:L15,'Historical Data'!L17:L19) -> -18856 | M25: =M22*-M9 -> -19308.691 | N25: =N22*-N9 -> -18869.969 | O25: =O22*-O9 -> -18484.091 | P25: =P22*-P9 -> -18143.902 | Q25: =Q22*-Q9 -> -17843.367
C26: EBITDA | H26: =SUM(H24:H25) -> 1608.1 | I26: =SUM(I24:I25) -> 1416.9 | J26: =SUM(J24:J25) -> 2001 | K26: =SUM(K24:K25) -> 2243 | L26: =SUM(L24:L25) -> 2286 | M26: =SUM(M24:M25) -> 1865.6165 | N26: =SUM(N24:N25) -> 1823.2269 | O26: =SUM(O24:O25) -> 1785.9432 | ... Q26: =SUM(Q24:Q25) -> 1724.0361
C27: Less: Depreciation & Amortization | H27: =-'Historical Data'!H16 -> -303.8 | I27: =-'Historical Data'!I16 -> -282.5 | J27: =-'Historical Data'!J16 -> -275 | K27: =-'Historical Data'!K16 -> -283 | L27: =-'Historical Data'!L16 -> -289 | M27: =M110 -> -221.52368 | N27: =N110 -> -164.48726 | O27: =O110 -> -121.16377 | P27: =P110 -> -88.346141 | Q27: =Q110 -> -63.56841
C28: EBIT | H28: =SUM(H26:H27) -> 1304.3 | I28: =SUM(I26:I27) -> 1134.4 | J28: =SUM(J26:J27) -> 1726 | K28: =SUM(K26:K27) -> 1960 | L28: =SUM(L26:L27) -> 1997 | M28: =SUM(M26:M27) -> 1644.0928 | N28: =SUM(N26:N27) -> 1658.7397 | O28: =SUM(O26:O27) -> 1664.7794 | ... Q28: =SUM(Q26:Q27) -> 1660.4677
C29: Less: Interest | H29: =-'Historical Data'!H20 -> -88 | I29: =-'Historical Data'!I20 -> -103.9 | J29: =-'Historical Data'!J20 -> -76 | K29: =-'Historical Data'!K20 -> -89 | L29: =-'Historical Data'!L20 -> -158 | M29: =M117 -> -129.43127 | N29: =N117 -> -62.365709 | O29: =O117 -> 0 | P29: =P117 -> 0 | Q29: =Q117 -> 0
C30: Other Income | H30: ='Historical Data'!H7+'Historical Data'!H26+'Historical Data'!H24+'Historical Data'!H35+'Historical Data'!H37 -> -117.3 | I30: ='Historical Data'!I7+'Historical Data'!I26+'Historical Data'!I24+'Historical Data'!I35+'Historical Data'!I37 -> 245.9 | J30: ='Historical Data'!J7+'Historical Data'!J26+'Historical Data'!J24+'Historical Data'!J35+'Historical Data'!J37 -> 204 | K30: ='Historical Data'!K7+'Historical Data'!K26+'Historical Data'!K24+'Historical Data'!K35+'Historical Data'!K37 -> 264 | L30: ='Historical Data'!L7+'Historical Data'!L26+'Historical Data'!L24+'Historical Data'!L35+'Historical Data'!L37 -> 518 | M30: =M22*M12 -> 223.45001 | N30: =N22*N12 -> 218.37289 | O30: =O22*O12 -> 213.90731 | P30: =P22*P12 -> 209.97048 | Q30: =Q22*Q12 -> 206.49254
C31: PBT | H31: =SUM(H28:H30) -> 1099 | I31: =SUM(I28:I30) -> 1276.4 | J31: =SUM(J28:J30) -> 1854 | K31: =SUM(K28:K30) -> 2135 | L31: =SUM(L28:L30) -> 2357 | M31: =SUM(M28:M30) -> 1738.1116 | N31: =SUM(N28:N30) -> 1814.7469 | O31: =SUM(O28:O30) -> 1878.6867 | ... Q31: =SUM(Q28:Q30) -> 1866.9603
C32: Less: Tax | H32: =-'Historical Data'!H32 -> -276 | I32: =-'Historical Data'!I32 -> -152.8 | J32: =-'Historical Data'!J32 -> -449 | K32: =-'Historical Data'!K32 -> -553 | L32: =-'Historical Data'!L32 -> -510 | M32: =M31*-M13 -> -378.35953 | N32: =N31*-N13 -> -395.04183 | O32: =O31*-O13 -> -408.96053 | P32: =P31*-P13 -> -408.09232 | Q32: =Q31*-Q13 -> -406.40786
C33: Profit After Tax | H33: =SUM(H31:H32) -> 823 | I33: =SUM(I31:I32) -> 1123.6 | J33: =SUM(J31:J32) -> 1405 | K33: =SUM(K31:K32) -> 1582 | L33: =SUM(L31:L32) -> 1847 | M33: =SUM(M31:M32) -> 1359.752 | N33: =SUM(N31:N32) -> 1419.705 | O33: =SUM(O31:O32) -> 1469.7262 | ... Q33: =SUM(Q31:Q32) -> 1460.5524
A35: BALANCE SHEET
B37: Assests
C38: Current Assest
D39: Cash & Bank | H39: ='Historical Data'!H64+'Historical Data'!H65 -> 60.3 | I39: ='Historical Data'!I64+'Historical Data'!I65 -> 883.3 | J39: ='Historical Data'!J64+'Historical Data'!J65 -> 1269 | K39: ='Historical Data'!K64+'Historical Data'!K65 -> 2030 | L39: ='Historical Data'!L64+'Historical Data'!L65 -> 1977 | M39: =M96 -> 3759.9988 | N39: =N96 -> 4930.9659 | O39: =O96 -> 6284.353 | P39: =P96 -> 7591.9715 | Q39: =Q96 -> 8860.9697
D40: Account Receivable | H40: ='Historical Data'!H63 -> 2373.6 | I40: ='Historical Data'!I63 -> 2434 | J40: ='Historical Data'!J63 -> 3056 | K40: ='Historical Data'!K63 -> 3410 | L40: ='Historical Data'!L63 -> 3609 | M40: =M22/365*M15 -> 2907.3637 | N40: =N22/365*N15 -> 2841.3041 | O40: =O22/365*O15 -> 2783.2013 | P40: =P22/365*P15 -> 2731.9782 | Q40: =Q22/365*Q15 -> 2686.7258
D41: Inventory | H41: ='Historical Data'!H61 -> 2156.7 | I41: ='Historical Data'!I61 -> 2230 | J41: ='Historical Data'!J61 -> 2063 | K41: ='Historical Data'!K61 -> 2305 | L41: ='Historical Data'!L61 -> 2668 | M41: =-M23/365*M16 -> 2229.0819 | N41: =-N23/365*N16 -> 2178.4339 | O41: =-O23/365*O16 -> 2133.8863 | P41: =-P23/365*P16 -> 2094.6135 | Q41: =-Q23/365*Q16 -> 2059.9184
D42: Other Current Assest | H42: =SUM('Historical Data'!H62,'Historical Data'!H66:H69) -> 572.8 | I42: =SUM('Historical Data'!I62,'Historical Data'!I66:I69) -> 687.3 | J42: =SUM('Historical Data'!J62,'Historical Data'!J66:J69) -> 989 | K42: =SUM('Historical Data'!K62,'Historical Data'!K66:K69) -> 1457 | L42: =SUM('Historical Data'!L62,'Historical Data'!L66:L69) -> 2309 | M42: =L42 -> 2309 | N42: =M42 -> 2309 | O42: =N42 -> 2309 | P42: =O42 -> 2309 | Q42: =P42 -> 2309
C44: Non-Current
D45: Plant, Property & Equipment | H45: ='Historical Data'!H43+'Historical Data'!H45 -> 1302.9 | I45: ='Historical Data'!I43+'Historical Data'!I45 -> 1045.1 | J45: ='Historical Data'!J43+'Historical Data'!J45 -> 881 | K45: ='Historical Data'!K43+'Historical Data'!K45 -> 922 | L45: ='Historical Data'!L43+'Historical Data'!L45 -> 909 | M45: =M111-M46 -> 655.38883 | N45: =N111-N46 -> 462.75191 | O45: =O111-O46 -> 316.8291 | P45: =P111-P46 -> 206.65548 | Q45: =Q111-Q46 -> 123.8039
D46: Intangible Assests | H46: ='Historical Data'!H47+'Historical Data'!H48 -> 366 | I46: ='Historical Data'!I47+'Historical Data'!I48 -> 372.7 | J46: ='Historical Data'!J47+'Historical Data'!J48 -> 349 | K46: ='Historical Data'!K47+'Historical Data'!K48 -> 329 | L46: ='Historical Data'!L47+'Historical Data'!L48 -> 76 | M46: =L46 -> 76 | N46: =M46 -> 76 | O46: =N46 -> 76 | P46: =O46 -> 76 | Q46: =P46 -> 76
D47: Goodwill | H47: ='Historical Data'!H46 -> 21 | I47: ='Historical Data'!I46 -> 1.3 | J47: ='Historical Data'!J46 -> 1 | K47: ='Historical Data'!K46 -> 1 | L47: ='Historical Data'!L46 -> 55 | M47: =L47 -> 55 | N47: =M47 -> 55 | O47: =N47 -> 55 | P47: =O47 -> 55 | Q47: =P47 -> 55
...

Sheet Scenarios
A1: United Spirits Limited
A2: Revenue Scenarios
D4: Scenarios | E4: Growth % | H4: =Model!M2 -> 2027 | I4: =Model!N2 -> 2028 | J4: =Model!O2 -> 2029 | K4: =Model!P2 -> 2030 | L4: =Model!Q2 -> 2031
D5: Base Case | E5: =AVERAGE(Model!I7:L7) -> -0.025246085 | H5: =E5 -> -0.025246085 | I5: =H5*(1-$E$8) -> -0.022721477 | J5: =I5*(1-$E$8) -> -0.020449329 | K5: =J5*(1-$E$8) -> -0.018404396 | L5: =K5*(1-$E$8) -> -0.016563957
D6: Bull Case | E6: =MAX(Model!I7:L7) -> 0.048351142 | H6: =E6 -> 0.048351142 | I6: =H6*(1-$E$8) -> 0.043516027 | J6: =I6*(1-$E$8) -> 0.039164425 | K6: =J6*(1-$E$8) -> 0.035247982 | L6: =K6*(1-$E$8) -> 0.031723184
D7: Bear Case | E7: =MIN(Model!I7:L7) -> -0.10451423 | H7: =E7 -> -0.10451423 | I7: =H7*(1-$E$8) -> -0.094062804 | J7: =I7*(1-$E$8) -> -0.084656523 | K7: =J7*(1-$E$8) -> -0.076190871 | L7: =K7*(1-$E$8) -> -0.068571784
D8: Annual growth tapering | E8: 0.1

Sheet Repayment
A1: United Spirits Limited
A2: Repayment of lease liabilities & Loan
D6: Lender / Facility | E6: Repayment Terms (per Note 40) | G6: Balance 31-Mar-26 | H6: FY27 | I6: FY28 | J6: FY29 | K6: FY30 | L6: FY31
D7: ICICI Bank – Working Capital Loan | E7: Revolving; payable on demand — treated as fully due in FY27 | G7: 6 | H7: 6 | I7: 0 | J7: 0 | K7: 0 | L7: 0
D8: Lease Liabilities (Ind AS 116) | E8: Per underlying lease terms; undiscounted maturity per Note 40 | G8: 461 | H8: 127 | I8: 78 | J8: 48.33 | K8: =J8 -> 48.33 | L8: =J8 -> 48.33
D11: Disclosed: due within 12 months, Lease Liabilities (Note 40) | G11: 127
D12: Disclosed: due 1–2 years, Lease Liabilities (Note 40) | G12: 78
D13: Disclosed: due 2–5 years, Lease Liabilities (Note 40) — spread straight-line across FY29–FY31 | G13: 145
D14: Disclosed: due beyond 5 years, Lease Liabilities (Note 40) — shown as single FY32+ lump sum | G14: 111
E15: Total Projected Repayment | G15: =SUM(G7:G14) -> 928 | H15: =SUM(H7:H14) -> 133 | I15: =SUM(I7:I14) -> 78 | J15: =SUM(J7:J14) -> 48.33 | K15: =SUM(K7:K14) -> 48.33 | L15: =SUM(L7:L14) -> 48.33

Sheet Market_Data
A1: United Spirits Limited
A2: Market Data
G5: Index
F6: Date | G6: Close Price
F7: 46230 | G7: 23995.95 | J7: Period (yrs) | L7: 9
F8: 46227 | G8: 23767.45
F9: 46226 | G9: 23869.6 | J9: Returns | L9: =_xlfn.RRI(L7,G2623,G7) -> 0.13038872
F10: 46225 | G10: 23996.25
F11: 46224 | G11: 24187.7
F12: 46223 | G12: 24238.5
F13: 46220 | G13: 24334.3
F14: 46219 | G14: 24072.75
F15: 46218 | G15: 24078.5
F16: 46217 | G16: 24052.05
F17: 46216 | G17: 24211
F18: 46213 | G18: 24206.9
F19: 46212 | G19: 23962.8
F20: 46211 | G20: 23882.05
F21: 46210 | G21: 24398.7
... F2623: 42370 | G2623: 7963.2

Sheet WACC
A1: United Spirits Limited
A2: Weighted-Average Cost of Capital (WACC)
A3: All Amounts Denominated in ₹ Cr Unless Otherwise Stated
A5: Comparable Companies Beta
H8: Equity | I8: Total | J8: Debt/ | K8: Debt/ | L8: Tax | M8: Levered | N8: Unlevered
D9: Company Name | H9: Value | I9: Debt | J9: Equity | K9: Capital | L9: Rate % | M9: Beta | N9: Beta
D10: Radico Khaitan Limited | H10: =Comps!N8 -> 62228.64 | I10: =Comps!L8 -> 498 | J10: =I10/H10 -> 0.008002746 | K10: =I10/(H10+I10) -> 0.0079392105 | L10: 0.3 | M10: 0.55 | N10: =M10/(1+J10*(1+K10)) -> 0.54559904
D11: Globus Spirits Limited | H11: =Comps!N9 -> 3403.25 | I11: =Comps!L9 -> 527 | J11: =I11/H11 -> 0.15485198 | K11: =I11/(H11+I11) -> 0.13408816 | L11: =L10 -> 0.3 | M11: 0.7 | N11: =M11/(1+J11*(1+K11)) -> 0.59543262
D12: Tilaknagar Industries Limited | H12: =Comps!N10 -> 12601.02 | I12: =Comps!L10 -> 47 | J12: =I12/H12 -> 0.0037298568 | K12: =I12/(H12+I12) -> 0.0037159967 | L12: =L11 -> 0.3 | M12: 0.65 | N12: =M12/(1+J12*(1+K12)) -> 0.64757566
D13: United Breweries Limited | H13: =Comps!N11 -> 38703.96 | I13: =Comps!L11 -> 1361 | J13: =I13/H13 -> 0.03516436 | K13: =I13/(H13+I13) -> 0.033969833 | L13: =L12 -> 0.3 | M13: 0.45 | N13: =M13/(1+J13*(1+K13)) -> 0.43421252
D14: Average | J14: =AVERAGE(J10:J13) -> 0.050437236 | K14: =AVERAGE(K10:K13) -> 0.044928301 | L14: =AVERAGE(L10:L13) -> 0.3 | M14: =AVERAGE(M10:M13) -> 0.5875 | N14: =AVERAGE(N10:N13) -> 0.55570496
D15: Median | J15: =MEDIAN(J10:J13) -> 0.021583553 | K15: =MEDIAN(K10:K13) -> 0.020954522 | L15: =MEDIAN(L10:L13) -> 0.3 | M15: =MEDIAN(M10:M13) -> 0.6 | N15: =MEDIAN(N10:N13) -> 0.57051583
D17: United Spirits | H17: =Comps!N16 -> 110302.43 | I17: =Comps!L16 -> 413
D19: WACC Calculation
C21: Target Capital Structure
D23: Proportion of Debt | I23: =K14 -> 0.044928301
D24: Proportion of Equity | I24: =1-I23 -> 0.9550717
C26: Current Capital Structure
D27: Market Cap | I27: =H17 -> 110302.43
D28: Total Debt | I28: =I17 -> 413
D29: Debt / Equity | I29: =I28/I27 -> 0.0037442511
C31: Current Capital Structure
D32: Pre-Tax Cost of Debt | I32: =Model!M11 -> 0.3133929
D33: Tax Rate | I33: =Model!M13 -> 0.21768426
D34: After-Tax Cost of Debt | I34: =I32*(1-I33) -> 0.2451722
C36: Cost of Equity
D37: Risk Free Rate | I37: 0.065
D38: Equity Market Return | I38: =Market_Data!L9 -> 0.13038872
D39: Equity Risk Premium | I39: =I38-I37 -> 0.065388717
D40: Levered Equity Beta | I40: =N15*(1+I29)*(1-I33) -> 0.44799466
D41: Cost of Equity | I41: =I37+I40*I39 -> 0.094293796
D43: WACC | I43: =(I23*I34)+(I41*I24) -> 0.10107251

Sheet Comps_Data
A1: United Spirits Limited
A2: Comps Data
D4: Company | H4: Ticker | I4: Price | J4: Shares | K4: Debt | L4: Cash | M4: Sales | N4: EBITDA | O4: Net Income
D5: United Spirits Limited | H5: UNITDSPR | I5: 1538 | J5: 72.735 | K5: 413 | L5: 1977 | M5: 12467 | N5: 2286 | O5: 1838
D7: Radico Khaitan Limited | H7: RADICO | I7: 4606 | J7: 13.44 | K7: 498 | L7: 174 | M7: 6228 | N7: 1138 | O7: 695
D8: Globus Spirits Limited | H8: GLOBUSSPR | I8: 915 | J8: 3.15 | K8: 527 | L8: 6 | M8: 2710 | N8: 256 | O8: 91
D9: Tilaknagar Industries Limited | H9: TI | I9: 454 | J9: 30.13 | K9: 47 | L9: 1125 | M9: 3016 | N9: 452 | O9: -36
D10: United Breweries Limited | H10: UBL | I10: 1434 | J10: 26.44 | K10: 1361 | L10: 572 | M10: 9442 | N10: 906 | O10: 396
D12: Source: www.screener.in

Sheet Comps
A1: United Spirits Limited
A2: Comps Valuation
I5: Market Data | P5: Financial Data | T5: Valuation
I6: Price | J6: Shares | K6: Market Cap | L6: Debt | M6: Cash | N6: EV | P6: Sales | Q6: EBITDA | R6: Earnings | T6: EV/Sales | U6: EV/EBITDA | V6: P/E
D7: Company Name | F7: Ticker | I7: (₹/share) | J7: Cr | K7: ₹ Cr | M7: & Equivalents | N7: ₹ Cr | P7: ₹ Cr | Q7: ₹ Cr | R7: ₹ Cr | T7: x | U7: x | V7: x
D8: Radico Khaitan Limited | F8: RADICO | I8: =Comps_Data!I7 -> 4606 | J8: =Comps_Data!J7 -> 13.44 | K8: =I8*J8 -> 61904.64 | L8: =Comps_Data!K7 -> 498 | M8: =Comps_Data!L7 -> 174 | N8: =K8+L8-M8 -> 62228.64 | P8: =Comps_Data!M7 -> 6228 | Q8: =Comps_Data!N7 -> 1138 | R8: =Comps_Data!O7 -> 695 | T8: =N8/P8 -> 9.9917534 | U8: =N8/Q8 -> 54.68246 | V8: =K8/R8 -> 89.071424
D9: Globus Spirits Limited | F9: GLOBUSSPR | I9: =Comps_Data!I8 -> 915 | J9: =Comps_Data!J8 -> 3.15 | K9: =I9*J9 -> 2882.25 | L9: =Comps_Data!K8 -> 527 | M9: =Comps_Data!L8 -> 6 | N9: =K9+L9-M9 -> 3403.25 | P9: =Comps_Data!M8 -> 2710 | Q9: =Comps_Data!N8 -> 256 | R9: =Comps_Data!O8 -> 91 | T9: =N9/P9 -> 1.2558118 | U9: =N9/Q9 -> 13.293945 | V9: =K9/R9 -> 31.673077
D10: Tilaknagar Industries Limited | F10: TI | I10: =Comps_Data!I9 -> 454 | J10: =Comps_Data!J9 -> 30.13 | K10: =I10*J10 -> 13679.02 | L10: =Comps_Data!K9 -> 47 | M10: =Comps_Data!L9 -> 1125 | N10: =K10+L10-M10 -> 12601.02 | P10: =Comps_Data!M9 -> 3016 | Q10: =Comps_Data!N9 -> 452 | R10: =Comps_Data!O9 -> -36 | T10: =N10/P10 -> 4.178057 | U10: =N10/Q10 -> 27.878363 | V10: =K10/R10 -> -379.97278
D11: United Breweries Limited | F11: UBL | I11: =Comps_Data!I10 -> 1434 | J11: =Comps_Data!J10 -> 26.44 | K11: =I11*J11 -> 37914.96 | L11: =Comps_Data!K10 -> 1361 | M11: =Comps_Data!L10 -> 572 | N11: =K11+L11-M11 -> 38703.96 | P11: =Comps_Data!M10 -> 9442 | Q11: =Comps_Data!N10 -> 906 | R11: =Comps_Data!O10 -> 396 | T11: =N11/P11 -> 4.0991273 | U11: =N11/Q11 -> 42.719603 | V11: =K11/R11 -> 95.744848
D13: Average | T13: =AVERAGE(T8:T11) -> 4.8811874 | U13: =AVERAGE(U8:U11) -> 34.643593 | V13: =AVERAGE(V8:V11) -> -40.870857
D14: Median | T14: =MEDIAN(T8:T11) -> 4.1385922 | U14: =MEDIAN(U8:U11) -> 35.298983 | V14: =MEDIAN(V8:V11) -> 60.372251
D16: United Spirits Limited | H16: UNITDSPR | I16: =Comps_Data!I5 -> 1538 | J16: =Comps_Data!J5 -> 72.735 | K16: =I16*J16 -> 111866.43 | L16: =Comps_Data!K5 -> 413 | M16: =Comps_Data!L5 -> 1977 | N16: =K16+L16-M16 -> 110302.43 | P16: =Comps_Data!M5 -> 12467 | Q16: =Comps_Data!N5 -> 2286 | R16: =Comps_Data!O5 -> 1838
D18: Metric | E18: Comps | H18: EV | I18: Net Debt | J18: Equity Value | K18: Shares | L18: Share Price
D19: EV/Revenue | E19: =T14 -> 4.1385922 | H19: =E19*P16 -> 51595.829 | I19: =$L$16-$M$16 -> -1564 | J19: =H19-I19 -> 53159.829 | K19: =J16 -> 72.735 | L19: =J19/K19 -> 730.86999
D20: EV/EBITDA | E20: =U14 -> 35.298983 | H20: =E20*Q16 -> 80693.475 | I20: =$L$16-$M$16 -> -1564 | J20: =H20-I20 -> 82257.475 | K20: =K19 -> 72.735 | L20: =J20/K20 -> 1130.9201
D21: PE | E21: =V14 -> 60.372251 | H21: =E21*R16 -> 110964.2 | I21: =$L$16-$M$16 -> -1564 | J21: =H21-I21 -> 112528.2 | K21: =K20 -> 72.735 | L21: =J21/K21 -> 1547.0983

Sheet Foot_Ball Field
A1: United Spirits Limited
A2: Football Field - Valuation Summary
A5: Football Field Data
F7: Comps | G7: DCF | H7: 52-week high/low | I7: Market Consensus
D8: High | F8: =F9 -> 1547.0983 | G8: =G9 -> 711.48 | H8: =H9 -> 1210.8 | I8: =I9 -> 1468.2
D9: High | F9: =Comps!L21 -> 1547.0983 | G9: 711.48 | H9: 1210.8 | I9: 1468.2 | J9: Choice Institutional Equities
D10: Low | F10: =Comps!L19 -> 730.86999 | G10: 393.47 | H10: 1563.4 | I10: =1318.8 -> 1318.8 | J10: Motilal Oswal
D11: Low | F11: =F10 -> 730.86999 | G11: =G10 -> 393.47 | H11: =H10 -> 1563.4 | I11: =I10 -> 1318.8
A13: Valuation Summary
